Workbook

Sheet Normalize
A1: NO | B1: KABUPATEN | C1: KECAMATAN | D1: DESA | E1: jeniskelamin | F1: KELAS | G1: class
A2: 1 | B2: 0 | C2: -0.47745389 | D2: -0.67397704 | E2: -1.0446386 | F2: 1 | G2: zona 1
A3: 2 | B3: 0 | C3: -0.10379432 | D3: -0.51583718 | E3: 0.94967147 | F3: 1 | G3: zona 2
A4: 3 | B4: 0 | C4: -0.47745389 | D4: -0.67397704 | E4: 0.94967147 | F4: 1 | G4: zona 1
A5: 4 | B5: 0 | C5: -0.10379432 | D5: -0.51583718 | E5: 0.94967147 | F5: 1 | G5: zona 2
A6: 5 | B6: 0 | C6: -0.47745389 | D6: -0.67397704 | E6: 0.94967147 | F6: 1 | G6: zona 1
A7: 6 | B7: 0 | C7: -0.10379432 | D7: -0.35769731 | E7: -1.0446386 | F7: 1 | G7: zona 2
A8: 7 | B8: 0 | C8: -0.10379432 | D8: -0.35769731 | E8: -1.0446386 | F8: 1 | G8: zona 2
A9: 8 | B9: 0 | C9: -0.47745389 | D9: -0.67397704 | E9: 0.94967147 | F9: 1 | G9: zona 1
A10: 9 | B10: 0 | C10: -0.47745389 | D10: -0.67397704 | E10: 0.94967147 | F10: 1 | G10: zona 1
A11: 10 | B11: 0 | C11: -0.10379432 | D11: -0.51583718 | E11: -1.0446386 | F11: 1 | G11: zona 2
A12: 11 | B12: 0 | C12: -0.10379432 | D12: -0.19955745 | E12: -1.0446386 | F12: 1 | G12: zona 2
A13: 12 | B13: 0 | C13: -0.10379432 | D13: -0.51583718 | E13: -1.0446386 | F13: 1 | G13: zona 2
... A127: 126 | B127: 0 | C127: -0.47745389 | D127: -0.67397704 | E127: -1.0446386 | F127: 6 | G127: zona 1

Sheet centeroid awal
A1: cluster | B1: NO | C1: KABUPATEN | D1: KECAMATAN | E1: DESA | F1: jeniskelamin | G1: KELAS
A2: zona 1 | B2: 1 | C2: 0 | D2: -0.47745389 | E2: -0.67397704 | F2: -1.0446386 | G2: 1
A3: zona 2 | B3: 2 | C3: 0 | D3: -0.10379432 | E3: -0.51583718 | F3: 0.94967147 | G3: 1
A4: zona 3 | B4: 21 | C4: 0 | D4: 0.64352481 | E4: 0.27486215 | F4: -1.0446386 | G4: 1

Sheet iterasi 1
A1: cluster | B1: NO | C1: KABUPATEN | D1: KECAMATAN | E1: DESA | F1: jeniskelamin | G1: KELAS | H1: KESIMPULAN ITERSI 1 | K1: CLASTER | L1: ANGGOTA
A2: 1 | B2: 1 | C2: 0 | D2: -0.5 | E2: -0.7 | F2: -1 | G2: 1 | K2: 1 | L2: =COUNTIF($L$10:$L$135,A2) -> 43
A3: 2 | B3: 2 | C3: 0 | D3: -0.1 | E3: -0.5 | F3: 0.9 | G3: 1 | K3: 2 | L3: =COUNTIF($L$10:$L$135,A3) -> 60
A4: 3 | B4: 21 | C4: 0 | D4: 0.6 | E4: 0.3 | F4: -1 | G4: 1 | K4: 3 | L4: =COUNTIF($L$10:$L$135,A4) -> 23
B8: NO | C8: DATA SET | H8: JARAK CETEROID | K8: TERDEKAT | L8: CLASTER YANG DI IKUTI
C9: KABUPATEN | D9: KECAMATAN | E9: DESA | F9: jeniskelamin | G9: KELAS | H9: 1 | I9: 2 | J9: 3
B10: 1 | C10: 0 | D10: -0.5 | E10: -0.7 | F10: -1 | G10: 1 | H10: =SQRT((($C10-$C$2)^2)+(($D10-$D$2)^2)+(($E10-$E$2)^2)+(($F10-$F$2)^2)+(($G10-$G$2)^2)) -> 0 | I10: =SQRT((($C10-$C$3)^2)+(($D10-$D$3)^2)+(($E10-$E$3)^2)+(($F10-$F$3)^2)+(($G10-$G$3)^2)) -> 1.9519221 | J10: =SQRT((($C10-$C$4)^2)+(($D10-$D$4)^2)+(($E10-$E$4)^2)+(($F10-$F$4)^2)+(($G10-$G$4)^2)) -> 1.4866069 | K10: =MIN(H10:J10) -> 0 | L10: =IF(K10=J10, $J$9, IF(K10=I10, $I$9, IF(K10=H10, $H$9))) -> 1
B11: 2 | C11: 0 | D11: -0.1 | E11: -0.5 | F11: 0.9 | G11: 1 | H11: =SQRT((($C11-$C$2)^2)+(($D11-$D$2)^2)+(($E11-$E$2)^2)+(($F11-$F$2)^2)+(($G11-$G$2)^2)) -> 1.9519221 | I11: =SQRT((($C11-$C$3)^2)+(($D11-$D$3)^2)+(($E11-$E$3)^2)+(($F11-$F$3)^2)+(($G11-$G$3)^2)) -> 0 | J11: =SQRT((($C11-$C$4)^2)+(($D11-$D$4)^2)+(($E11-$E$4)^2)+(($F11-$F$4)^2)+(($G11-$G$4)^2)) -> 2.1771541 | K11: =MIN(H11:J11) -> 0 | L11: =IF(K11=J11, $J$9, IF(K11=I11, $I$9, IF(K11=H11, $H$9))) -> 2
B12: 3 | C12: 0 | D12: -0.5 | E12: -0.7 | F12: 0.9 | G12: 1 | H12: =SQRT((($C12-$C$2)^2)+(($D12-$D$2)^2)+(($E12-$E$2)^2)+(($F12-$F$2)^2)+(($G12-$G$2)^2)) -> 1.9 | I12: =SQRT((($C12-$C$3)^2)+(($D12-$D$3)^2)+(($E12-$E$3)^2)+(($F12-$F$3)^2)+(($G12-$G$3)^2)) -> 0.4472136 | J12: =SQRT((($C12-$C$4)^2)+(($D12-$D$4)^2)+(($E12-$E$4)^2)+(($F12-$F$4)^2)+(($G12-$G$4)^2)) -> 2.4124676 | K12: =MIN(H12:J12) -> 0.4472136 | L12: =IF(K12=J12, $J$9, IF(K12=I12, $I$9, IF(K12=H12, $H$9))) -> 2
B13: 4 | C13: 0 | D13: -0.1 | E13: -0.5 | F13: 0.9 | G13: 1 | H13: =SQRT((($C13-$C$2)^2)+(($D13-$D$2)^2)+(($E13-$E$2)^2)+(($F13-$F$2)^2)+(($G13-$G$2)^2)) -> 1.9519221 | I13: =SQRT((($C13-$C$3)^2)+(($D13-$D$3)^2)+(($E13-$E$3)^2)+(($F13-$F$3)^2)+(($G13-$G$3)^2)) -> 0 | J13: =SQRT((($C13-$C$4)^2)+(($D13-$D$4)^2)+(($E13-$E$4)^2)+(($F13-$F$4)^2)+(($G13-$G$4)^2)) -> 2.1771541 | K13: =MIN(H13:J13) -> 0 | L13: =IF(K13=J13, $J$9, IF(K13=I13, $I$9, IF(K13=H13, $H$9))) -> 2
B14: 5 | C14: 0 | D14: -0.5 | E14: -0.7 | F14: 0.9 | G14: 1 | H14: =SQRT((($C14-$C$2)^2)+(($D14-$D$2)^2)+(($E14-$E$2)^2)+(($F14-$F$2)^2)+(($G14-$G$2)^2)) -> 1.9 | I14: =SQRT((($C14-$C$3)^2)+(($D14-$D$3)^2)+(($E14-$E$3)^2)+(($F14-$F$3)^2)+(($G14-$G$3)^2)) -> 0.4472136 | J14: =SQRT((($C14-$C$4)^2)+(($D14-$D$4)^2)+(($E14-$E$4)^2)+(($F14-$F$4)^2)+(($G14-$G$4)^2)) -> 2.4124676 | K14: =MIN(H14:J14) -> 0.4472136 | L14: =IF(K14=J14, $J$9, IF(K14=I14, $I$9, IF(K14=H14, $H$9))) -> 2
B15: 6 | C15: 0 | D15: -0.1 | E15: -0.4 | F15: -1 | G15: 1 | H15: =SQRT((($C15-$C$2)^2)+(($D15-$D$2)^2)+(($E15-$E$2)^2)+(($F15-$F$2)^2)+(($G15-$G$2)^2)) -> 0.5 | I15: =SQRT((($C15-$C$3)^2)+(($D15-$D$3)^2)+(($E15-$E$3)^2)+(($F15-$F$3)^2)+(($G15-$G$3)^2)) -> 1.9026298 | J15: =SQRT((($C15-$C$4)^2)+(($D15-$D$4)^2)+(($E15-$E$4)^2)+(($F15-$F$4)^2)+(($G15-$G$4)^2)) -> 0.98994949 | K15: =MIN(H15:J15) -> 0.5 | L15: =IF(K15=J15, $J$9, IF(K15=I15, $I$9, IF(K15=H15, $H$9))) -> 1
B16: 7 | C16: 0 | D16: -0.1 | E16: -0.4 | F16: -1 | G16: 1 | H16: =SQRT((($C16-$C$2)^2)+(($D16-$D$2)^2)+(($E16-$E$2)^2)+(($F16-$F$2)^2)+(($G16-$G$2)^2)) -> 0.5 | I16: =SQRT((($C16-$C$3)^2)+(($D16-$D$3)^2)+(($E16-$E$3)^2)+(($F16-$F$3)^2)+(($G16-$G$3)^2)) -> 1.9026298 | J16: =SQRT((($C16-$C$4)^2)+(($D16-$D$4)^2)+(($E16-$E$4)^2)+(($F16-$F$4)^2)+(($G16-$G$4)^2)) -> 0.98994949 | K16: =MIN(H16:J16) -> 0.5 | L16: =IF(K16=J16, $J$9, IF(K16=I16, $I$9, IF(K16=H16, $H$9))) -> 1
B17: 8 | C17: 0 | D17: -0.5 | E17: -0.7 | F17: 0.9 | G17: 1 | H17: =SQRT((($C17-$C$2)^2)+(($D17-$D$2)^2)+(($E17-$E$2)^2)+(($F17-$F$2)^2)+(($G17-$G$2)^2)) -> 1.9 | I17: =SQRT((($C17-$C$3)^2)+(($D17-$D$3)^2)+(($E17-$E$3)^2)+(($F17-$F$3)^2)+(($G17-$G$3)^2)) -> 0.4472136 | J17: =SQRT((($C17-$C$4)^2)+(($D17-$D$4)^2)+(($E17-$E$4)^2)+(($F17-$F$4)^2)+(($G17-$G$4)^2)) -> 2.4124676 | K17: =MIN(H17:J17) -> 0.4472136 | L17: =IF(K17=J17, $J$9, IF(K17=I17, $I$9, IF(K17=H17, $H$9))) -> 2
B18: 9 | C18: 0 | D18: -0.5 | E18: -0.7 | F18: 0.9 | G18: 1 | H18: =SQRT((($C18-$C$2)^2)+(($D18-$D$2)^2)+(($E18-$E$2)^2)+(($F18-$F$2)^2)+(($G18-$G$2)^2)) -> 1.9 | I18: =SQRT((($C18-$C$3)^2)+(($D18-$D$3)^2)+(($E18-$E$3)^2)+(($F18-$F$3)^2)+(($G18-$G$3)^2)) -> 0.4472136 | J18: =SQRT((($C18-$C$4)^2)+(($D18-$D$4)^2)+(($E18-$E$4)^2)+(($F18-$F$4)^2)+(($G18-$G$4)^2)) -> 2.4124676 | K18: =MIN(H18:J18) -> 0.4472136 | L18: =IF(K18=J18, $J$9, IF(K18=I18, $I$9, IF(K18=H18, $H$9))) -> 2
B19: 10 | C19: 0 | D19: -0.1 | E19: -0.5 | F19: -1 | G19: 1 | H19: =SQRT((($C19-$C$2)^2)+(($D19-$D$2)^2)+(($E19-$E$2)^2)+(($F19-$F$2)^2)+(($G19-$G$2)^2)) -> 0.4472136 | I19: =SQRT((($C19-$C$3)^2)+(($D19-$D$3)^2)+(($E19-$E$3)^2)+(($F19-$F$3)^2)+(($G19-$G$3)^2)) -> 1.9 | J19: =SQRT((($C19-$C$4)^2)+(($D19-$D$4)^2)+(($E19-$E$4)^2)+(($F19-$F$4)^2)+(($G19-$G$4)^2)) -> 1.0630146 | K19: =MIN(H19:J19) -> 0.4472136 | L19: =IF(K19=J19, $J$9, IF(K19=I19, $I$9, IF(K19=H19, $H$9))) -> 1
B20: 11 | C20: 0 | D20: -0.1 | E20: -0.2 | F20: -1 | G20: 1 | H20: =SQRT((($C20-$C$2)^2)+(($D20-$D$2)^2)+(($E20-$E$2)^2)+(($F20-$F$2)^2)+(($G20-$G$2)^2)) -> 0.64031242 | I20: =SQRT((($C20-$C$3)^2)+(($D20-$D$3)^2)+(($E20-$E$3)^2)+(($F20-$F$3)^2)+(($G20-$G$3)^2)) -> 1.9235384 | J20: =SQRT((($C20-$C$4)^2)+(($D20-$D$4)^2)+(($E20-$E$4)^2)+(($F20-$F$4)^2)+(($G20-$G$4)^2)) -> 0.86023253 | K20: =MIN(H20:J20) -> 0.64031242 | L20: =IF(K20=J20, $J$9, IF(K20=I20, $I$9, IF(K20=H20, $H$9))) -> 1
B21: 12 | C21: 0 | D21: -0.1 | E21: -0.5 | F21: -1 | G21: 1 | H21: =SQRT((($C21-$C$2)^2)+(($D21-$D$2)^2)+(($E21-$E$2)^2)+(($F21-$F$2)^2)+(($G21-$G$2)^2)) -> 0.4472136 | I21: =SQRT((($C21-$C$3)^2)+(($D21-$D$3)^2)+(($E21-$E$3)^2)+(($F21-$F$3)^2)+(($G21-$G$3)^2)) -> 1.9 | J21: =SQRT((($C21-$C$4)^2)+(($D21-$D$4)^2)+(($E21-$E$4)^2)+(($F21-$F$4)^2)+(($G21-$G$4)^2)) -> 1.0630146 | K21: =MIN(H21:J21) -> 0.4472136 | L21: =IF(K21=J21, $J$9, IF(K21=I21, $I$9, IF(K21=H21, $H$9))) -> 1
... B135: 126 | C135: 0 | D135: -0.5 | E135: -0.7 | F135: -1 | G135: 6 | H135: =SQRT((($C135-$C$2)^2)+(($D135-$D$2)^2)+(($E135-$E$2)^2)+(($F135-$F$2)^2)+(($G135-$G$2)^2)) -> 5 | I135: =SQRT((($C135-$C$3)^2)+(($D135-$D$3)^2)+(($E135-$E$3)^2)+(($F135-$F$3)^2)+(($G135-$G$3)^2)) -> 5.3674948 | J135: =SQRT((($C135-$C$4)^2)+(($D135-$D$4)^2)+(($E135-$E$4)^2)+(($F135-$F$4)^2)+(($G135-$G$4)^2)) -> 5.2163205 | K135: =MIN(H135:J135) -> 5 | L135: =IF(K135=J135, $J$9, IF(K135=I135, $I$9, IF(K135=H135, $H$9))) -> 1

Sheet iterasi 2
A1: cluster | B1: ANGGOTA | C1: KABUPATEN | D1: KECAMATAN | E1: DESA | F1: jeniskelamin | G1: KELAS | H1: KESIMPULAN ITERSI 1 | K1: CLASTER | L1: ANGGOTA
A2: 1 | B2: ='iterasi 1'!L2 -> 43 | C2: =SUMIF('iterasi 1'!$L$10:$L$135,$A$2,'iterasi 1'!C$10:C$135)/$B$2 -> 0 | D2: =SUMIF('iterasi 1'!$L$10:$L$135,$A$2,'iterasi 1'!D$10:D$135)/$B$2 -> -0.34186047 | E2: =SUMIF('iterasi 1'!$L$10:$L$135,$A$2,'iterasi 1'!E$10:E$135)/$B$2 -> -0.51395349 | F2: =SUMIF('iterasi 1'!$L$10:$L$135,$A$2,'iterasi 1'!F$10:F$135)/$B$2 -> -1 | G2: =SUMIF('iterasi 1'!$L$10:$L$135,$A$2,'iterasi 1'!G$10:G$135)/$B$2 -> 3.4418605 | K2: 1 | L2: =COUNTIF($L$10:$L$135,A2) -> 51
A3: 2 | B3: ='iterasi 1'!L3 -> 60 | C3: =SUMIF('iterasi 1'!$L$10:$L$135,$A$3,'iterasi 1'!C$10:C$135)/$B$3 -> 0 | D3: =SUMIF('iterasi 1'!$L$10:$L$135,$A$3,'iterasi 1'!D$10:D$135)/$B$3 -> -0.30666667 | E3: =SUMIF('iterasi 1'!$L$10:$L$135,$A$3,'iterasi 1'!E$10:E$135)/$B$3 -> -0.3 | F3: =SUMIF('iterasi 1'!$L$10:$L$135,$A$3,'iterasi 1'!F$10:F$135)/$B$3 -> 0.9 | G3: =SUMIF('iterasi 1'!$L$10:$L$135,$A$3,'iterasi 1'!G$10:G$135)/$B$3 -> 2.9166667 | K3: 2 | L3: =COUNTIF($L$10:$L$135,A3) -> 60
A4: 3 | B4: ='iterasi 1'!L4 -> 23 | C4: =SUMIF('iterasi 1'!$L$10:$L$135,$A$4,'iterasi 1'!C$10:C$135)/$B$4 -> 0 | D4: =SUMIF('iterasi 1'!$L$10:$L$135,$A$4,'iterasi 1'!D$10:D$135)/$B$4 -> 1.3913043 | E4: =SUMIF('iterasi 1'!$L$10:$L$135,$A$4,'iterasi 1'!E$10:E$135)/$B$4 -> 1.6521739 | F4: =SUMIF('iterasi 1'!$L$10:$L$135,$A$4,'iterasi 1'!F$10:F$135)/$B$4 -> -0.50434783 | G4: =SUMIF('iterasi 1'!$L$10:$L$135,$A$4,'iterasi 1'!G$10:G$135)/$B$4 -> 3.4347826 | K4: 3 | L4: =COUNTIF($L$10:$L$135,A4) -> 15
B8: NO | C8: DATA SET | H8: JARAK CETEROID | K8: TERDEKAT | L8: CLASTER YANG DI IKUTI
C9: KABUPATEN | D9: KECAMATAN | E9: DESA | F9: jeniskelamin | G9: KELAS | H9: 1 | I9: 2 | J9: 3
B10: 1 | C10: 0 | D10: -0.5 | E10: -0.7 | F10: -1 | G10: 1 | H10: =SQRT((($C10-$C$2)^2)+(($D10-$D$2)^2)+(($E10-$E$2)^2)+(($F10-$F$2)^2)+(($G10-$G$2)^2)) -> 2.4540383 | I10: =SQRT((($C10-$C$3)^2)+(($D10-$D$3)^2)+(($E10-$E$3)^2)+(($F10-$F$3)^2)+(($G10-$G$3)^2)) -> 2.7351396 | J10: =SQRT((($C10-$C$4)^2)+(($D10-$D$4)^2)+(($E10-$E$4)^2)+(($F10-$F$4)^2)+(($G10-$G$4)^2)) -> 3.9094234 | K10: =MIN(H10:J10) -> 2.4540383 | L10: =IF(K10=J10, $J$9, IF(K10=I10, $I$9, IF(K10=H10, $H$9))) -> 1
B11: 2 | C11: 0 | D11: -0.1 | E11: -0.5 | F11: 0.9 | G11: 1 | H11: =SQRT((($C11-$C$2)^2)+(($D11-$D$2)^2)+(($E11-$E$2)^2)+(($F11-$F$2)^2)+(($G11-$G$2)^2)) -> 3.1034455 | I11: =SQRT((($C11-$C$3)^2)+(($D11-$D$3)^2)+(($E11-$E$3)^2)+(($F11-$F$3)^2)+(($G11-$G$3)^2)) -> 1.9381234 | J11: =SQRT((($C11-$C$4)^2)+(($D11-$D$4)^2)+(($E11-$E$4)^2)+(($F11-$F$4)^2)+(($G11-$G$4)^2)) -> 3.84138 | K11: =MIN(H11:J11) -> 1.9381234 | L11: =IF(K11=J11, $J$9, IF(K11=I11, $I$9, IF(K11=H11, $H$9))) -> 2
B12: 3 | C12: 0 | D12: -0.5 | E12: -0.7 | F12: 0.9 | G12: 1 | H12: =SQRT((($C12-$C$2)^2)+(($D12-$D$2)^2)+(($E12-$E$2)^2)+(($F12-$F$2)^2)+(($G12-$G$2)^2)) -> 3.1035953 | I12: =SQRT((($C12-$C$3)^2)+(($D12-$D$3)^2)+(($E12-$E$3)^2)+(($F12-$F$3)^2)+(($G12-$G$3)^2)) -> 1.9674829 | J12: =SQRT((($C12-$C$4)^2)+(($D12-$D$4)^2)+(($E12-$E$4)^2)+(($F12-$F$4)^2)+(($G12-$G$4)^2)) -> 4.1243319 | K12: =MIN(H12:J12) -> 1.9674829 | L12: =IF(K12=J12, $J$9, IF(K12=I12, $I$9, IF(K12=H12, $H$9))) -> 2
B13: 4 | C13: 0 | D13: -0.1 | E13: -0.5 | F13: 0.9 | G13: 1 | H13: =SQRT((($C13-$C$2)^2)+(($D13-$D$2)^2)+(($E13-$E$2)^2)+(($F13-$F$2)^2)+(($G13-$G$2)^2)) -> 3.1034455 | I13: =SQRT((($C13-$C$3)^2)+(($D13-$D$3)^2)+(($E13-$E$3)^2)+(($F13-$F$3)^2)+(($G13-$G$3)^2)) -> 1.9381234 | J13: =SQRT((($C13-$C$4)^2)+(($D13-$D$4)^2)+(($E13-$E$4)^2)+(($F13-$F$4)^2)+(($G13-$G$4)^2)) -> 3.84138 | K13: =MIN(H13:J13) -> 1.9381234 | L13: =IF(K13=J13, $J$9, IF(K13=I13, $I$9, IF(K13=H13, $H$9))) -> 2
B14: 5 | C14: 0 | D14: -0.5 | E14: -0.7 | F14: 0.9 | G14: 1 | H14: =SQRT((($C14-$C$2)^2)+(($D14-$D$2)^2)+(($E14-$E$2)^2)+(($F14-$F$2)^2)+(($G14-$G$2)^2)) -> 3.1035953 | I14: =SQRT((($C14-$C$3)^2)+(($D14-$D$3)^2)+(($E14-$E$3)^2)+(($F14-$F$3)^2)+(($G14-$G$3)^2)) -> 1.9674829 | J14: =SQRT((($C14-$C$4)^2)+(($D14-$D$4)^2)+(($E14-$E$4)^2)+(($F14-$F$4)^2)+(($G14-$G$4)^2)) -> 4.1243319 | K14: =MIN(H14:J14) -> 1.9674829 | L14: =IF(K14=J14, $J$9, IF(K14=I14, $I$9, IF(K14=H14, $H$9))) -> 2
B15: 6 | C15: 0 | D15: -0.1 | E15: -0.4 | F15: -1 | G15: 1 | H15: =SQRT((($C15-$C$2)^2)+(($D15-$D$2)^2)+(($E15-$E$2)^2)+(($F15-$F$2)^2)+(($G15-$G$2)^2)) -> 2.4564536 | I15: =SQRT((($C15-$C$3)^2)+(($D15-$D$3)^2)+(($E15-$E$3)^2)+(($F15-$F$3)^2)+(($G15-$G$3)^2)) -> 2.7085646 | J15: =SQRT((($C15-$C$4)^2)+(($D15-$D$4)^2)+(($E15-$E$4)^2)+(($F15-$F$4)^2)+(($G15-$G$4)^2)) -> 3.5509497 | K15: =MIN(H15:J15) -> 2.4564536 | L15: =IF(K15=J15, $J$9, IF(K15=I15, $I$9, IF(K15=H15, $H$9))) -> 1
B16: 7 | C16: 0 | D16: -0.1 | E16: -0.4 | F16: -1 | G16: 1 | H16: =SQRT((($C16-$C$2)^2)+(($D16-$D$2)^2)+(($E16-$E$2)^2)+(($F16-$F$2)^2)+(($G16-$G$2)^2)) -> 2.4564536 | I16: =SQRT((($C16-$C$3)^2)+(($D16-$D$3)^2)+(($E16-$E$3)^2)+(($F16-$F$3)^2)+(($G16-$G$3)^2)) -> 2.7085646 | J16: =SQRT((($C16-$C$4)^2)+(($D16-$D$4)^2)+(($E16-$E$4)^2)+(($F16-$F$4)^2)+(($G16-$G$4)^2)) -> 3.5509497 | K16: =MIN(H16:J16) -> 2.4564536 | L16: =IF(K16=J16, $J$9, IF(K16=I16, $I$9, IF(K16=H16, $H$9))) -> 1
B17: 8 | C17: 0 | D17: -0.5 | E17: -0.7 | F17: 0.9 | G17: 1 | H17: =SQRT((($C17-$C$2)^2)+(($D17-$D$2)^2)+(($E17-$E$2)^2)+(($F17-$F$2)^2)+(($G17-$G$2)^2)) -> 3.1035953 | I17: =SQRT((($C17-$C$3)^2)+(($D17-$D$3)^2)+(($E17-$E$3)^2)+(($F17-$F$3)^2)+(($G17-$G$3)^2)) -> 1.9674829 | J17: =SQRT((($C17-$C$4)^2)+(($D17-$D$4)^2)+(($E17-$E$4)^2)+(($F17-$F$4)^2)+(($G17-$G$4)^2)) -> 4.1243319 | K17: =MIN(H17:J17) -> 1.9674829 | L17: =IF(K17=J17, $J$9, IF(K17=I17, $I$9, IF(K17=H17, $H$9))) -> 2
B18: 9 | C18: 0 | D18: -0.5 | E18: -0.7 | F18: 0.9 | G18: 1 | H18: =SQRT((($C18-$C$2)^2)+(($D18-$D$2)^2)+(($E18-$E$2)^2)+(($F18-$F$2)^2)+(($G18-$G$2)^2)) -> 3.1035953 | I18: =SQRT((($C18-$C$3)^2)+(($D18-$D$3)^2)+(($E18-$E$3)^2)+(($F18-$F$3)^2)+(($G18-$G$3)^2)) -> 1.9674829 | J18: =SQRT((($C18-$C$4)^2)+(($D18-$D$4)^2)+(($E18-$E$4)^2)+(($F18-$F$4)^2)+(($G18-$G$4)^2)) -> 4.1243319 | K18: =MIN(H18:J18) -> 1.9674829 | L18: =IF(K18=J18, $J$9, IF(K18=I18, $I$9, IF(K18=H18, $H$9))) -> 2
B19: 10 | C19: 0 | D19: -0.1 | E19: -0.5 | F19: -1 | G19: 1 | H19: =SQRT((($C19-$C$2)^2)+(($D19-$D$2)^2)+(($E19-$E$2)^2)+(($F19-$F$2)^2)+(($G19-$G$2)^2)) -> 2.4538488 | I19: =SQRT((($C19-$C$3)^2)+(($D19-$D$3)^2)+(($E19-$E$3)^2)+(($F19-$F$3)^2)+(($G19-$G$3)^2)) -> 2.7140969 | J19: =SQRT((($C19-$C$4)^2)+(($D19-$D$4)^2)+(($E19-$E$4)^2)+(($F19-$F$4)^2)+(($G19-$G$4)^2)) -> 3.6096646 | K19: =MIN(H19:J19) -> 2.4538488 | L19: =IF(K19=J19, $J$9, IF(K19=I19, $I$9, IF(K19=H19, $H$9))) -> 1
B20: 11 | C20: 0 | D20: -0.1 | E20: -0.2 | F20: -1 | G20: 1 | H20: =SQRT((($C20-$C$2)^2)+(($D20-$D$2)^2)+(($E20-$E$2)^2)+(($F20-$F$2)^2)+(($G20-$G$2)^2)) -> 2.473812 | I20: =SQRT((($C20-$C$3)^2)+(($D20-$D$3)^2)+(($E20-$E$3)^2)+(($F20-$F$3)^2)+(($G20-$G$3)^2)) -> 2.7085646 | J20: =SQRT((($C20-$C$4)^2)+(($D20-$D$4)^2)+(($E20-$E$4)^2)+(($F20-$F$4)^2)+(($G20-$G$4)^2)) -> 3.4392404 | K20: =MIN(H20:J20) -> 2.473812 | L20: =IF(K20=J20, $J$9, IF(K20=I20, $I$9, IF(K20=H20, $H$9))) -> 1
B21: 12 | C21: 0 | D21: -0.1 | E21: -0.5 | F21: -1 | G21: 1 | H21: =SQRT((($C21-$C$2)^2)+(($D21-$D$2)^2)+(($E21-$E$2)^2)+(($F21-$F$2)^2)+(($G21-$G$2)^2)) -> 2.4538488 | I21: =SQRT((($C21-$C$3)^2)+(($D21-$D$3)^2)+(($E21-$E$3)^2)+(($F21-$F$3)^2)+(($G21-$G$3)^2)) -> 2.7140969 | J21: =SQRT((($C21-$C$4)^2)+(($D21-$D$4)^2)+(($E21-$E$4)^2)+(($F21-$F$4)^2)+(($G21-$G$4)^2)) -> 3.6096646 | K21: =MIN(H21:J21) -> 2.4538488 | L21: =IF(K21=J21, $J$9, IF(K21=I21, $I$9, IF(K21=H21, $H$9))) -> 1
... B135: 126 | C135: 0 | D135: -0.5 | E135: -0.7 | F135: -1 | G135: 6 | H135: =SQRT((($C135-$C$2)^2)+(($D135-$D$2)^2)+(($E135-$E$2)^2)+(($F135-$F$2)^2)+(($G135-$G$2)^2)) -> 2.5697664 | I135: =SQRT((($C135-$C$3)^2)+(($D135-$D$3)^2)+(($E135-$E$3)^2)+(($F135-$F$3)^2)+(($G135-$G$3)^2)) -> 3.6488796 | J135: =SQRT((($C135-$C$4)^2)+(($D135-$D$4)^2)+(($E135-$E$4)^2)+(($F135-$F$4)^2)+(($G135-$G$4)^2)) -> 3.9919626 | K135: =MIN(H135:J135) -> 2.5697664 | L135: =IF(K135=J135, $J$9, IF(K135=I135, $I$9, IF(K135=H135, $H$9))) -> 1

Sheet iterasi 3
A1: cluster | B1: ANGGOTA | C1: KABUPATEN | D1: KECAMATAN | E1: DESA | F1: jeniskelamin | G1: KELAS | H1: KESIMPULAN ITERSI 1 | K1: CLASTER | L1: ANGGOTA
A2: 1 | B2: ='iterasi 1'!L2 -> 43 | C2: =SUMIF('iterasi 2'!$L$10:$L$135,$A$2,'iterasi 2'!C$10:C$135)/$B$2 -> 0 | D2: =SUMIF('iterasi 2'!$L$10:$L$135,$A$2,'iterasi 2'!D$10:D$135)/$B$2 -> -0.34418605 | E2: =SUMIF('iterasi 2'!$L$10:$L$135,$A$2,'iterasi 2'!E$10:E$135)/$B$2 -> -0.43488372 | F2: =SUMIF('iterasi 2'!$L$10:$L$135,$A$2,'iterasi 2'!F$10:F$135)/$B$2 -> -1.1860465 | G2: =SUMIF('iterasi 2'!$L$10:$L$135,$A$2,'iterasi 2'!G$10:G$135)/$B$2 -> 3.7906977 | K2: 1 | L2: =COUNTIF($L$10:$L$135,A2) -> 40
A3: 2 | B3: ='iterasi 1'!L3 -> 60 | C3: =SUMIF('iterasi 2'!$L$10:$L$135,$A$3,'iterasi 2'!C$10:C$135)/$B$3 -> 0 | D3: =SUMIF('iterasi 2'!$L$10:$L$135,$A$3,'iterasi 2'!D$10:D$135)/$B$3 -> -0.30666667 | E3: =SUMIF('iterasi 2'!$L$10:$L$135,$A$3,'iterasi 2'!E$10:E$135)/$B$3 -> -0.3 | F3: =SUMIF('iterasi 2'!$L$10:$L$135,$A$3,'iterasi 2'!F$10:F$135)/$B$3 -> 0.9 | G3: =SUMIF('iterasi 2'!$L$10:$L$135,$A$3,'iterasi 2'!G$10:G$135)/$B$3 -> 2.9166667 | K3: 2 | L3: =COUNTIF($L$10:$L$135,A3) -> 68
A4: 3 | B4: ='iterasi 1'!L4 -> 23 | C4: =SUMIF('iterasi 2'!$L$10:$L$135,$A$4,'iterasi 2'!C$10:C$135)/$B$4 -> 0 | D4: =SUMIF('iterasi 2'!$L$10:$L$135,$A$4,'iterasi 2'!D$10:D$135)/$B$4 -> 1.3956522 | E4: =SUMIF('iterasi 2'!$L$10:$L$135,$A$4,'iterasi 2'!E$10:E$135)/$B$4 -> 1.5043478 | F4: =SUMIF('iterasi 2'!$L$10:$L$135,$A$4,'iterasi 2'!F$10:F$135)/$B$4 -> -0.15652174 | G4: =SUMIF('iterasi 2'!$L$10:$L$135,$A$4,'iterasi 2'!G$10:G$135)/$B$4 -> 2.7826087 | K4: 3 | L4: =COUNTIF($L$10:$L$135,A4) -> 18
B8: NO | C8: DATA SET | H8: JARAK CETEROID | K8: TERDEKAT | L8: CLASTER YANG DI IKUTI
C9: KABUPATEN | D9: KECAMATAN | E9: DESA | F9: jeniskelamin | G9: KELAS | H9: 1 | I9: 2 | J9: 3
B10: 1 | C10: 0 | D10: -0.5 | E10: -0.7 | F10: -1 | G10: 1 | H10: =SQRT((($C10-$C$2)^2)+(($D10-$D$2)^2)+(($E10-$E$2)^2)+(($F10-$F$2)^2)+(($G10-$G$2)^2)) -> 2.8137469 | I10: =SQRT((($C10-$C$3)^2)+(($D10-$D$3)^2)+(($E10-$E$3)^2)+(($F10-$F$3)^2)+(($G10-$G$3)^2)) -> 2.7351396 | J10: =SQRT((($C10-$C$4)^2)+(($D10-$D$4)^2)+(($E10-$E$4)^2)+(($F10-$F$4)^2)+(($G10-$G$4)^2)) -> 3.5130892 | K10: =MIN(H10:J10) -> 2.7351396 | L10: =IF(K10=J10, $J$9, IF(K10=I10, $I$9, IF(K10=H10, $H$9))) -> 2
B11: 2 | C11: 0 | D11: -0.1 | E11: -0.5 | F11: 0.9 | G11: 1 | H11: =SQRT((($C11-$C$2)^2)+(($D11-$D$2)^2)+(($E11-$E$2)^2)+(($F11-$F$2)^2)+(($G11-$G$2)^2)) -> 3.4933437 | I11: =SQRT((($C11-$C$3)^2)+(($D11-$D$3)^2)+(($E11-$E$3)^2)+(($F11-$F$3)^2)+(($G11-$G$3)^2)) -> 1.9381234 | J11: =SQRT((($C11-$C$4)^2)+(($D11-$D$4)^2)+(($E11-$E$4)^2)+(($F11-$F$4)^2)+(($G11-$G$4)^2)) -> 3.2478174 | K11: =MIN(H11:J11) -> 1.9381234 | L11: =IF(K11=J11, $J$9, IF(K11=I11, $I$9, IF(K11=H11, $H$9))) -> 2
B12: 3 | C12: 0 | D12: -0.5 | E12: -0.7 | F12: 0.9 | G12: 1 | H12: =SQRT((($C12-$C$2)^2)+(($D12-$D$2)^2)+(($E12-$E$2)^2)+(($F12-$F$2)^2)+(($G12-$G$2)^2)) -> 3.4977347 | I12: =SQRT((($C12-$C$3)^2)+(($D12-$D$3)^2)+(($E12-$E$3)^2)+(($F12-$F$3)^2)+(($G12-$G$3)^2)) -> 1.9674829 | J12: =SQRT((($C12-$C$4)^2)+(($D12-$D$4)^2)+(($E12-$E$4)^2)+(($F12-$F$4)^2)+(($G12-$G$4)^2)) -> 3.5702351 | K12: =MIN(H12:J12) -> 1.9674829 | L12: =IF(K12=J12, $J$9, IF(K12=I12, $I$9, IF(K12=H12, $H$9))) -> 2
B13: 4 | C13: 0 | D13: -0.1 | E13: -0.5 | F13: 0.9 | G13: 1 | H13: =SQRT((($C13-$C$2)^2)+(($D13-$D$2)^2)+(($E13-$E$2)^2)+(($F13-$F$2)^2)+(($G13-$G$2)^2)) -> 3.4933437 | I13: =SQRT((($C13-$C$3)^2)+(($D13-$D$3)^2)+(($E13-$E$3)^2)+(($F13-$F$3)^2)+(($G13-$G$3)^2)) -> 1.9381234 | J13: =SQRT((($C13-$C$4)^2)+(($D13-$D$4)^2)+(($E13-$E$4)^2)+(($F13-$F$4)^2)+(($G13-$G$4)^2)) -> 3.2478174 | K13: =MIN(H13:J13) -> 1.9381234 | L13: =IF(K13=J13, $J$9, IF(K13=I13, $I$9, IF(K13=H13, $H$9))) -> 2
B14: 5 | C14: 0 | D14: -0.5 | E14: -0.7 | F14: 0.9 | G14: 1 | H14: =SQRT((($C14-$C$2)^2)+(($D14-$D$2)^2)+(($E14-$E$2)^2)+(($F14-$F$2)^2)+(($G14-$G$2)^2)) -> 3.4977347 | I14: =SQRT((($C14-$C$3)^2)+(($D14-$D$3)^2)+(($E14-$E$3)^2)+(($F14-$F$3)^2)+(($G14-$G$3)^2)) -> 1.9674829 | J14: =SQRT((($C14-$C$4)^2)+(($D14-$D$4)^2)+(($E14-$E$4)^2)+(($F14-$F$4)^2)+(($G14-$G$4)^2)) -> 3.5702351 | K14: =MIN(H14:J14) -> 1.9674829 | L14: =IF(K14=J14, $J$9, IF(K14=I14, $I$9, IF(K14=H14, $H$9))) -> 2
B15: 6 | C15: 0 | D15: -0.1 | E15: -0.4 | F15: -1 | G15: 1 | H15: =SQRT((($C15-$C$2)^2)+(($D15-$D$2)^2)+(($E15-$E$2)^2)+(($F15-$F$2)^2)+(($G15-$G$2)^2)) -> 2.8077483 | I15: =SQRT((($C15-$C$3)^2)+(($D15-$D$3)^2)+(($E15-$E$3)^2)+(($F15-$F$3)^2)+(($G15-$G$3)^2)) -> 2.7085646 | J15: =SQRT((($C15-$C$4)^2)+(($D15-$D$4)^2)+(($E15-$E$4)^2)+(($F15-$F$4)^2)+(($G15-$G$4)^2)) -> 3.1229258 | K15: =MIN(H15:J15) -> 2.7085646 | L15: =IF(K15=J15, $J$9, IF(K15=I15, $I$9, IF(K15=H15, $H$9))) -> 2
B16: 7 | C16: 0 | D16: -0.1 | E16: -0.4 | F16: -1 | G16: 1 | H16: =SQRT((($C16-$C$2)^2)+(($D16-$D$2)^2)+(($E16-$E$2)^2)+(($F16-$F$2)^2)+(($G16-$G$2)^2)) -> 2.8077483 | I16: =SQRT((($C16-$C$3)^2)+(($D16-$D$3)^2)+(($E16-$E$3)^2)+(($F16-$F$3)^2)+(($G16-$G$3)^2)) -> 2.7085646 | J16: =SQRT((($C16-$C$4)^2)+(($D16-$D$4)^2)+(($E16-$E$4)^2)+(($F16-$F$4)^2)+(($G16-$G$4)^2)) -> 3.1229258 | K16: =MIN(H16:J16) -> 2.7085646 | L16: =IF(K16=J16, $J$9, IF(K16=I16, $I$9, IF(K16=H16, $H$9))) -> 2
B17: 8 | C17: 0 | D17: -0.5 | E17: -0.7 | F17: 0.9 | G17: 1 | H17: =SQRT((($C17-$C$2)^2)+(($D17-$D$2)^2)+(($E17-$E$2)^2)+(($F17-$F$2)^2)+(($G17-$G$2)^2)) -> 3.4977347 | I17: =SQRT((($C17-$C$3)^2)+(($D17-$D$3)^2)+(($E17-$E$3)^2)+(($F17-$F$3)^2)+(($G17-$G$3)^2)) -> 1.9674829 | J17: =SQRT((($C17-$C$4)^2)+(($D17-$D$4)^2)+(($E17-$E$4)^2)+(($F17-$F$4)^2)+(($G17-$G$4)^2)) -> 3.5702351 | K17: =MIN(H17:J17) -> 1.9674829 | L17: =IF(K17=J17, $J$9, IF(K17=I17, $I$9, IF(K17=H17, $H$9))) -> 2
B18: 9 | C18: 0 | D18: -0.5 | E18: -0.7 | F18: 0.9 | G18: 1 | H18: =SQRT((($C18-$C$2)^2)+(($D18-$D$2)^2)+(($E18-$E$2)^2)+(($F18-$F$2)^2)+(($G18-$G$2)^2)) -> 3.4977347 | I18: =SQRT((($C18-$C$3)^2)+(($D18-$D$3)^2)+(($E18-$E$3)^2)+(($F18-$F$3)^2)+(($G18-$G$3)^2)) -> 1.9674829 | J18: =SQRT((($C18-$C$4)^2)+(($D18-$D$4)^2)+(($E18-$E$4)^2)+(($F18-$F$4)^2)+(($G18-$G$4)^2)) -> 3.5702351 | K18: =MIN(H18:J18) -> 1.9674829 | L18: =IF(K18=J18, $J$9, IF(K18=I18, $I$9, IF(K18=H18, $H$9))) -> 2
B19: 10 | C19: 0 | D19: -0.1 | E19: -0.5 | F19: -1 | G19: 1 | H19: =SQRT((($C19-$C$2)^2)+(($D19-$D$2)^2)+(($E19-$E$2)^2)+(($F19-$F$2)^2)+(($G19-$G$2)^2)) -> 2.8082866 | I19: =SQRT((($C19-$C$3)^2)+(($D19-$D$3)^2)+(($E19-$E$3)^2)+(($F19-$F$3)^2)+(($G19-$G$3)^2)) -> 2.7140969 | J19: =SQRT((($C19-$C$4)^2)+(($D19-$D$4)^2)+(($E19-$E$4)^2)+(($F19-$F$4)^2)+(($G19-$G$4)^2)) -> 3.1848917 | K19: =MIN(H19:J19) -> 2.7140969 | L19: =IF(K19=J19, $J$9, IF(K19=I19, $I$9, IF(K19=H19, $H$9))) -> 2
B20: 11 | C20: 0 | D20: -0.1 | E20: -0.2 | F20: -1 | G20: 1 | H20: =SQRT((($C20-$C$2)^2)+(($D20-$D$2)^2)+(($E20-$E$2)^2)+(($F20-$F$2)^2)+(($G20-$G$2)^2)) -> 2.8173399 | I20: =SQRT((($C20-$C$3)^2)+(($D20-$D$3)^2)+(($E20-$E$3)^2)+(($F20-$F$3)^2)+(($G20-$G$3)^2)) -> 2.7085646 | J20: =SQRT((($C20-$C$4)^2)+(($D20-$D$4)^2)+(($E20-$E$4)^2)+(($F20-$F$4)^2)+(($G20-$G$4)^2)) -> 3.00515 | K20: =MIN(H20:J20) -> 2.7085646 | L20: =IF(K20=J20, $J$9, IF(K20=I20, $I$9, IF(K20=H20, $H$9))) -> 2
B21: 12 | C21: 0 | D21: -0.1 | E21: -0.5 | F21: -1 | G21: 1 | H21: =SQRT((($C21-$C$2)^2)+(($D21-$D$2)^2)+(($E21-$E$2)^2)+(($F21-$F$2)^2)+(($G21-$G$2)^2)) -> 2.8082866 | I21: =SQRT((($C21-$C$3)^2)+(($D21-$D$3)^2)+(($E21-$E$3)^2)+(($F21-$F$3)^2)+(($G21-$G$3)^2)) -> 2.7140969 | J21: =SQRT((($C21-$C$4)^2)+(($D21-$D$4)^2)+(($E21-$E$4)^2)+(($F21-$F$4)^2)+(($G21-$G$4)^2)) -> 3.1848917 | K21: =MIN(H21:J21) -> 2.7140969 | L21: =IF(K21=J21, $J$9, IF(K21=I21, $I$9, IF(K21=H21, $H$9))) -> 2
... B135: 126 | C135: 0 | D135: -0.5 | E135: -0.7 | F135: -1 | G135: 6 | H135: =SQRT((($C135-$C$2)^2)+(($D135-$D$2)^2)+(($E135-$E$2)^2)+(($F135-$F$2)^2)+(($G135-$G$2)^2)) -> 2.2383464 | I135: =SQRT((($C135-$C$3)^2)+(($D135-$D$3)^2)+(($E135-$E$3)^2)+(($F135-$F$3)^2)+(($G135-$G$3)^2)) -> 3.6488796 | J135: =SQRT((($C135-$C$4)^2)+(($D135-$D$4)^2)+(($E135-$E$4)^2)+(($F135-$F$4)^2)+(($G135-$G$4)^2)) -> 4.4176588 | K135: =MIN(H135:J135) -> 2.2383464 | L135: =IF(K135=J135, $J$9, IF(K135=I135, $I$9, IF(K135=H135, $H$9))) -> 1

Sheet iterasi 4
A1: cluster | B1: ANGGOTA | C1: KABUPATEN | D1: KECAMATAN | E1: DESA | F1: jeniskelamin | G1: KELAS | H1: KESIMPULAN ITERSI 1 | K1: CLASTER | L1: ANGGOTA
A2: 1 | B2: ='iterasi 1'!L2 -> 43 | C2: =SUMIF('iterasi 3'!$L$10:$L$135,$A$2,'iterasi 3'!C$10:C$135)/$B$2 -> 0 | D2: =SUMIF('iterasi 3'!$L$10:$L$135,$A$2,'iterasi 3'!D$10:D$135)/$B$2 -> -0.3255814 | E2: =SUMIF('iterasi 3'!$L$10:$L$135,$A$2,'iterasi 3'!E$10:E$135)/$B$2 -> -0.35348837 | F2: =SUMIF('iterasi 3'!$L$10:$L$135,$A$2,'iterasi 3'!F$10:F$135)/$B$2 -> -0.79767442 | G2: =SUMIF('iterasi 3'!$L$10:$L$135,$A$2,'iterasi 3'!G$10:G$135)/$B$2 -> 3.9069767 | K2: 1 | L2: =COUNTIF($L$10:$L$135,A2) -> 44
A3: 2 | B3: ='iterasi 1'!L3 -> 60 | C3: =SUMIF('iterasi 3'!$L$10:$L$135,$A$3,'iterasi 3'!C$10:C$135)/$B$3 -> 0 | D3: =SUMIF('iterasi 3'!$L$10:$L$135,$A$3,'iterasi 3'!D$10:D$135)/$B$3 -> -0.33333333 | E3: =SUMIF('iterasi 3'!$L$10:$L$135,$A$3,'iterasi 3'!E$10:E$135)/$B$3 -> -0.35666667 | F3: =SUMIF('iterasi 3'!$L$10:$L$135,$A$3,'iterasi 3'!F$10:F$135)/$B$3 -> 0.67166667 | G3: =SUMIF('iterasi 3'!$L$10:$L$135,$A$3,'iterasi 3'!G$10:G$135)/$B$3 -> 2.8 | K3: 2 | L3: =COUNTIF($L$10:$L$135,A3) -> 64
A4: 3 | B4: ='iterasi 1'!L4 -> 23 | C4: =SUMIF('iterasi 3'!$L$10:$L$135,$A$4,'iterasi 3'!C$10:C$135)/$B$4 -> 0 | D4: =SUMIF('iterasi 3'!$L$10:$L$135,$A$4,'iterasi 3'!D$10:D$135)/$B$4 -> 1.4304348 | E4: =SUMIF('iterasi 3'!$L$10:$L$135,$A$4,'iterasi 3'!E$10:E$135)/$B$4 -> 1.5 | F4: =SUMIF('iterasi 3'!$L$10:$L$135,$A$4,'iterasi 3'!F$10:F$135)/$B$4 -> -0.28695652 | G4: =SUMIF('iterasi 3'!$L$10:$L$135,$A$4,'iterasi 3'!G$10:G$135)/$B$4 -> 2.8695652 | K4: 3 | L4: =COUNTIF($L$10:$L$135,A4) -> 18
B8: NO | C8: DATA SET | H8: JARAK CETEROID | K8: TERDEKAT | L8: CLASTER YANG DI IKUTI
C9: KABUPATEN | D9: KECAMATAN | E9: DESA | F9: jeniskelamin | G9: KELAS | H9: 1 | I9: 2 | J9: 3
B10: 1 | C10: 0 | D10: -0.5 | E10: -0.7 | F10: -1 | G10: 1 | H10: =SQRT((($C10-$C$2)^2)+(($D10-$D$2)^2)+(($E10-$E$2)^2)+(($F10-$F$2)^2)+(($G10-$G$2)^2)) -> 2.9397179 | I10: =SQRT((($C10-$C$3)^2)+(($D10-$D$3)^2)+(($E10-$E$3)^2)+(($F10-$F$3)^2)+(($G10-$G$3)^2)) -> 2.4859857 | J10: =SQRT((($C10-$C$4)^2)+(($D10-$D$4)^2)+(($E10-$E$4)^2)+(($F10-$F$4)^2)+(($G10-$G$4)^2)) -> 3.5454596 | K10: =MIN(H10:J10) -> 2.4859857 | L10: =IF(K10=J10, $J$9, IF(K10=I10, $I$9, IF(K10=H10, $H$9))) -> 2
B11: 2 | C11: 0 | D11: -0.1 | E11: -0.5 | F11: 0.9 | G11: 1 | H11: =SQRT((($C11-$C$2)^2)+(($D11-$D$2)^2)+(($E11-$E$2)^2)+(($F11-$F$2)^2)+(($G11-$G$2)^2)) -> 3.3771238 | I11: =SQRT((($C11-$C$3)^2)+(($D11-$D$3)^2)+(($E11-$E$3)^2)+(($F11-$F$3)^2)+(($G11-$G$3)^2)) -> 1.8349728 | J11: =SQRT((($C11-$C$4)^2)+(($D11-$D$4)^2)+(($E11-$E$4)^2)+(($F11-$F$4)^2)+(($G11-$G$4)^2)) -> 3.3535609 | K11: =MIN(H11:J11) -> 1.8349728 | L11: =IF(K11=J11, $J$9, IF(K11=I11, $I$9, IF(K11=H11, $H$9))) -> 2
B12: 3 | C12: 0 | D12: -0.5 | E12: -0.7 | F12: 0.9 | G12: 1 | H12: =SQRT((($C12-$C$2)^2)+(($D12-$D$2)^2)+(($E12-$E$2)^2)+(($F12-$F$2)^2)+(($G12-$G$2)^2)) -> 3.388673 | I12: =SQRT((($C12-$C$3)^2)+(($D12-$D$3)^2)+(($E12-$E$3)^2)+(($F12-$F$3)^2)+(($G12-$G$3)^2)) -> 1.8541283 | J12: =SQRT((($C12-$C$4)^2)+(($D12-$D$4)^2)+(($E12-$E$4)^2)+(($F12-$F$4)^2)+(($G12-$G$4)^2)) -> 3.6702477 | K12: =MIN(H12:J12) -> 1.8541283 | L12: =IF(K12=J12, $J$9, IF(K12=I12, $I$9, IF(K12=H12, $H$9))) -> 2
B13: 4 | C13: 0 | D13: -0.1 | E13: -0.5 | F13: 0.9 | G13: 1 | H13: =SQRT((($C13-$C$2)^2)+(($D13-$D$2)^2)+(($E13-$E$2)^2)+(($F13-$F$2)^2)+(($G13-$G$2)^2)) -> 3.3771238 | I13: =SQRT((($C13-$C$3)^2)+(($D13-$D$3)^2)+(($E13-$E$3)^2)+(($F13-$F$3)^2)+(($G13-$G$3)^2)) -> 1.8349728 | J13: =SQRT((($C13-$C$4)^2)+(($D13-$D$4)^2)+(($E13-$E$4)^2)+(($F13-$F$4)^2)+(($G13-$G$4)^2)) -> 3.3535609 | K13: =MIN(H13:J13) -> 1.8349728 | L13: =IF(K13=J13, $J$9, IF(K13=I13, $I$9, IF(K13=H13, $H$9))) -> 2
B14: 5 | C14: 0 | D14: -0.5 | E14: -0.7 | F14: 0.9 | G14: 1 | H14: =SQRT((($C14-$C$2)^2)+(($D14-$D$2)^2)+(($E14-$E$2)^2)+(($F14-$F$2)^2)+(($G14-$G$2)^2)) -> 3.388673 | I14: =SQRT((($C14-$C$3)^2)+(($D14-$D$3)^2)+(($E14-$E$3)^2)+(($F14-$F$3)^2)+(($G14-$G$3)^2)) -> 1.8541283 | J14: =SQRT((($C14-$C$4)^2)+(($D14-$D$4)^2)+(($E14-$E$4)^2)+(($F14-$F$4)^2)+(($G14-$G$4)^2)) -> 3.6702477 | K14: =MIN(H14:J14) -> 1.8541283 | L14: =IF(K14=J14, $J$9, IF(K14=I14, $I$9, IF(K14=H14, $H$9))) -> 2
B15: 6 | C15: 0 | D15: -0.1 | E15: -0.4 | F15: -1 | G15: 1 | H15: =SQRT((($C15-$C$2)^2)+(($D15-$D$2)^2)+(($E15-$E$2)^2)+(($F15-$F$2)^2)+(($G15-$G$2)^2)) -> 2.9230976 | I15: =SQRT((($C15-$C$3)^2)+(($D15-$D$3)^2)+(($E15-$E$3)^2)+(($F15-$F$3)^2)+(($G15-$G$3)^2)) -> 2.4679529 | J15: =SQRT((($C15-$C$4)^2)+(($D15-$D$4)^2)+(($E15-$E$4)^2)+(($F15-$F$4)^2)+(($G15-$G$4)^2)) -> 3.1553028 | K15: =MIN(H15:J15) -> 2.4679529 | L15: =IF(K15=J15, $J$9, IF(K15=I15, $I$9, IF(K15=H15, $H$9))) -> 2
B16: 7 | C16: 0 | D16: -0.1 | E16: -0.4 | F16: -1 | G16: 1 | H16: =SQRT((($C16-$C$2)^2)+(($D16-$D$2)^2)+(($E16-$E$2)^2)+(($F16-$F$2)^2)+(($G16-$G$2)^2)) -> 2.9230976 | I16: =SQRT((($C16-$C$3)^2)+(($D16-$D$3)^2)+(($E16-$E$3)^2)+(($F16-$F$3)^2)+(($G16-$G$3)^2)) -> 2.4679529 | J16: =SQRT((($C16-$C$4)^2)+(($D16-$D$4)^2)+(($E16-$E$4)^2)+(($F16-$F$4)^2)+(($G16-$G$4)^2)) -> 3.1553028 | K16: =MIN(H16:J16) -> 2.4679529 | L16: =IF(K16=J16, $J$9, IF(K16=I16, $I$9, IF(K16=H16, $H$9))) -> 2
B17: 8 | C17: 0 | D17: -0.5 | E17: -0.7 | F17: 0.9 | G17: 1 | H17: =SQRT((($C17-$C$2)^2)+(($D17-$D$2)^2)+(($E17-$E$2)^2)+(($F17-$F$2)^2)+(($G17-$G$2)^2)) -> 3.388673 | I17: =SQRT((($C17-$C$3)^2)+(($D17-$D$3)^2)+(($E17-$E$3)^2)+(($F17-$F$3)^2)+(($G17-$G$3)^2)) -> 1.8541283 | J17: =SQRT((($C17-$C$4)^2)+(($D17-$D$4)^2)+(($E17-$E$4)^2)+(($F17-$F$4)^2)+(($G17-$G$4)^2)) -> 3.6702477 | K17: =MIN(H17:J17) -> 1.8541283 | L17: =IF(K17=J17, $J$9, IF(K17=I17, $I$9, IF(K17=H17, $H$9))) -> 2
B18: 9 | C18: 0 | D18: -0.5 | E18: -0.7 | F18: 0.9 | G18: 1 | H18: =SQRT((($C18-$C$2)^2)+(($D18-$D$2)^2)+(($E18-$E$2)^2)+(($F18-$F$2)^2)+(($G18-$G$2)^2)) -> 3.388673 | I18: =SQRT((($C18-$C$3)^2)+(($D18-$D$3)^2)+(($E18-$E$3)^2)+(($F18-$F$3)^2)+(($G18-$G$3)^2)) -> 1.8541283 | J18: =SQRT((($C18-$C$4)^2)+(($D18-$D$4)^2)+(($E18-$E$4)^2)+(($F18-$F$4)^2)+(($G18-$G$4)^2)) -> 3.6702477 | K18: =MIN(H18:J18) -> 1.8541283 | L18: =IF(K18=J18, $J$9, IF(K18=I18, $I$9, IF(K18=H18, $H$9))) -> 2
B19: 10 | C19: 0 | D19: -0.1 | E19: -0.5 | F19: -1 | G19: 1 | H19: =SQRT((($C19-$C$2)^2)+(($D19-$D$2)^2)+(($E19-$E$2)^2)+(($F19-$F$2)^2)+(($G19-$G$2)^2)) -> 2.9263975 | I19: =SQRT((($C19-$C$3)^2)+(($D19-$D$3)^2)+(($E19-$E$3)^2)+(($F19-$F$3)^2)+(($G19-$G$3)^2)) -> 2.4717318 | J19: =SQRT((($C19-$C$4)^2)+(($D19-$D$4)^2)+(($E19-$E$4)^2)+(($F19-$F$4)^2)+(($G19-$G$4)^2)) -> 3.2165099 | K19: =MIN(H19:J19) -> 2.4717318 | L19: =IF(K19=J19, $J$9, IF(K19=I19, $I$9, IF(K19=H19, $H$9))) -> 2
B20: 11 | C20: 0 | D20: -0.1 | E20: -0.2 | F20: -1 | G20: 1 | H20: =SQRT((($C20-$C$2)^2)+(($D20-$D$2)^2)+(($E20-$E$2)^2)+(($F20-$F$2)^2)+(($G20-$G$2)^2)) -> 2.926755 | I20: =SQRT((($C20-$C$3)^2)+(($D20-$D$3)^2)+(($E20-$E$3)^2)+(($F20-$F$3)^2)+(($G20-$G$3)^2)) -> 2.4725409 | J20: =SQRT((($C20-$C$4)^2)+(($D20-$D$4)^2)+(($E20-$E$4)^2)+(($F20-$F$4)^2)+(($G20-$G$4)^2)) -> 3.0390682 | K20: =MIN(H20:J20) -> 2.4725409 | L20: =IF(K20=J20, $J$9, IF(K20=I20, $I$9, IF(K20=H20, $H$9))) -> 2
B21: 12 | C21: 0 | D21: -0.1 | E21: -0.5 | F21: -1 | G21: 1 | H21: =SQRT((($C21-$C$2)^2)+(($D21-$D$2)^2)+(($E21-$E$2)^2)+(($F21-$F$2)^2)+(($G21-$G$2)^2)) -> 2.9263975 | I21: =SQRT((($C21-$C$3)^2)+(($D21-$D$3)^2)+(($E21-$E$3)^2)+(($F21-$F$3)^2)+(($G21-$G$3)^2)) -> 2.4717318 | J21: =SQRT((($C21-$C$4)^2)+(($D21-$D$4)^2)+(($E21-$E$4)^2)+(($F21-$F$4)^2)+(($G21-$G$4)^2)) -> 3.2165099 | K21: =MIN(H21:J21) -> 2.4717318 | L21: =IF(K21=J21, $J$9, IF(K21=I21, $I$9, IF(K21=H21, $H$9))) -> 2
... B135: 126 | C135: 0 | D135: -0.5 | E135: -0.7 | F135: -1 | G135: 6 | H135: =SQRT((($C135-$C$2)^2)+(($D135-$D$2)^2)+(($E135-$E$2)^2)+(($F135-$F$2)^2)+(($G135-$G$2)^2)) -> 2.1382643 | I135: =SQRT((($C135-$C$3)^2)+(($D135-$D$3)^2)+(($E135-$E$3)^2)+(($F135-$F$3)^2)+(($G135-$G$3)^2)) -> 3.6304442 | J135: =SQRT((($C135-$C$4)^2)+(($D135-$D$4)^2)+(($E135-$E$4)^2)+(($F135-$F$4)^2)+(($G135-$G$4)^2)) -> 4.3444944 | K135: =MIN(H135:J135) -> 2.1382643 | L135: =IF(K135=J135, $J$9, IF(K135=I135, $I$9, IF(K135=H135, $H$9))) -> 1

Sheet iterasi 5
A1: cluster | B1: ANGGOTA | C1: KABUPATEN | D1: KECAMATAN | E1: DESA | F1: jeniskelamin | G1: KELAS | H1: KESIMPULAN ITERSI 1 | K1: CLASTER | L1: ANGGOTA
A2: 1 | B2: ='iterasi 1'!L2 -> 43 | C2: =SUMIF('iterasi 4'!$L$10:$L$135,$A$2,'iterasi 4'!C$10:C$135)/$B$2 -> 0 | D2: =SUMIF('iterasi 4'!$L$10:$L$135,$A$2,'iterasi 4'!D$10:D$135)/$B$2 -> -0.37209302 | E2: =SUMIF('iterasi 4'!$L$10:$L$135,$A$2,'iterasi 4'!E$10:E$135)/$B$2 -> -0.43953488 | F2: =SUMIF('iterasi 4'!$L$10:$L$135,$A$2,'iterasi 4'!F$10:F$135)/$B$2 -> -0.5372093 | G2: =SUMIF('iterasi 4'!$L$10:$L$135,$A$2,'iterasi 4'!G$10:G$135)/$B$2 -> 4.6511628 | K2: 1 | L2: =COUNTIF($L$10:$L$135,A2) -> 41
A3: 2 | B3: ='iterasi 1'!L3 -> 60 | C3: =SUMIF('iterasi 4'!$L$10:$L$135,$A$3,'iterasi 4'!C$10:C$135)/$B$3 -> 0 | D3: =SUMIF('iterasi 4'!$L$10:$L$135,$A$3,'iterasi 4'!D$10:D$135)/$B$3 -> -0.3 | E3: =SUMIF('iterasi 4'!$L$10:$L$135,$A$3,'iterasi 4'!E$10:E$135)/$B$3 -> -0.295 | F3: =SUMIF('iterasi 4'!$L$10:$L$135,$A$3,'iterasi 4'!F$10:F$135)/$B$3 -> 0.485 | G3: =SUMIF('iterasi 4'!$L$10:$L$135,$A$3,'iterasi 4'!G$10:G$135)/$B$3 -> 2.2666667 | K3: 2 | L3: =COUNTIF($L$10:$L$135,A3) -> 70
A4: 3 | B4: ='iterasi 1'!L4 -> 23 | C4: =SUMIF('iterasi 4'!$L$10:$L$135,$A$4,'iterasi 4'!C$10:C$135)/$B$4 -> 0 | D4: =SUMIF('iterasi 4'!$L$10:$L$135,$A$4,'iterasi 4'!D$10:D$135)/$B$4 -> 1.4304348 | E4: =SUMIF('iterasi 4'!$L$10:$L$135,$A$4,'iterasi 4'!E$10:E$135)/$B$4 -> 1.5 | F4: =SUMIF('iterasi 4'!$L$10:$L$135,$A$4,'iterasi 4'!F$10:F$135)/$B$4 -> -0.28695652 | G4: =SUMIF('iterasi 4'!$L$10:$L$135,$A$4,'iterasi 4'!G$10:G$135)/$B$4 -> 2.8695652 | K4: 3 | L4: =COUNTIF($L$10:$L$135,A4) -> 15
B8: NO | C8: DATA SET | H8: JARAK CETEROID | K8: TERDEKAT | L8: CLASTER YANG DI IKUTI
C9: KABUPATEN | D9: KECAMATAN | E9: DESA | F9: jeniskelamin | G9: KELAS | H9: 1 | I9: 2 | J9: 3
B10: 1 | C10: 0 | D10: -0.5 | E10: -0.7 | F10: -1 | G10: 1 | H10: =SQRT((($C10-$C$2)^2)+(($D10-$D$2)^2)+(($E10-$E$2)^2)+(($F10-$F$2)^2)+(($G10-$G$2)^2)) -> 3.6917973 | I10: =SQRT((($C10-$C$3)^2)+(($D10-$D$3)^2)+(($E10-$E$3)^2)+(($F10-$F$3)^2)+(($G10-$G$3)^2)) -> 2.0034207 | J10: =SQRT((($C10-$C$4)^2)+(($D10-$D$4)^2)+(($E10-$E$4)^2)+(($F10-$F$4)^2)+(($G10-$G$4)^2)) -> 3.5454596 | K10: =MIN(H10:J10) -> 2.0034207 | L10: =IF(K10=J10, $J$9, IF(K10=I10, $I$9, IF(K10=H10, $H$9))) -> 2
B11: 2 | C11: 0 | D11: -0.1 | E11: -0.5 | F11: 0.9 | G11: 1 | H11: =SQRT((($C11-$C$2)^2)+(($D11-$D$2)^2)+(($E11-$E$2)^2)+(($F11-$F$2)^2)+(($G11-$G$2)^2)) -> 3.9337324 | I11: =SQRT((($C11-$C$3)^2)+(($D11-$D$3)^2)+(($E11-$E$3)^2)+(($F11-$F$3)^2)+(($G11-$G$3)^2)) -> 1.3633394 | J11: =SQRT((($C11-$C$4)^2)+(($D11-$D$4)^2)+(($E11-$E$4)^2)+(($F11-$F$4)^2)+(($G11-$G$4)^2)) -> 3.3535609 | K11: =MIN(H11:J11) -> 1.3633394 | L11: =IF(K11=J11, $J$9, IF(K11=I11, $I$9, IF(K11=H11, $H$9))) -> 2
B12: 3 | C12: 0 | D12: -0.5 | E12: -0.7 | F12: 0.9 | G12: 1 | H12: =SQRT((($C12-$C$2)^2)+(($D12-$D$2)^2)+(($E12-$E$2)^2)+(($F12-$F$2)^2)+(($G12-$G$2)^2)) -> 3.93456 | I12: =SQRT((($C12-$C$3)^2)+(($D12-$D$3)^2)+(($E12-$E$3)^2)+(($F12-$F$3)^2)+(($G12-$G$3)^2)) -> 1.4073715 | J12: =SQRT((($C12-$C$4)^2)+(($D12-$D$4)^2)+(($E12-$E$4)^2)+(($F12-$F$4)^2)+(($G12-$G$4)^2)) -> 3.6702477 | K12: =MIN(H12:J12) -> 1.4073715 | L12: =IF(K12=J12, $J$9, IF(K12=I12, $I$9, IF(K12=H12, $H$9))) -> 2
B13: 4 | C13: 0 | D13: -0.1 | E13: -0.5 | F13: 0.9 | G13: 1 | H13: =SQRT((($C13-$C$2)^2)+(($D13-$D$2)^2)+(($E13-$E$2)^2)+(($F13-$F$2)^2)+(($G13-$G$2)^2)) -> 3.9337324 | I13: =SQRT((($C13-$C$3)^2)+(($D13-$D$3)^2)+(($E13-$E$3)^2)+(($F13-$F$3)^2)+(($G13-$G$3)^2)) -> 1.3633394 | J13: =SQRT((($C13-$C$4)^2)+(($D13-$D$4)^2)+(($E13-$E$4)^2)+(($F13-$F$4)^2)+(($G13-$G$4)^2)) -> 3.3535609 | K13: =MIN(H13:J13) -> 1.3633394 | L13: =IF(K13=J13, $J$9, IF(K13=I13, $I$9, IF(K13=H13, $H$9))) -> 2
B14: 5 | C14: 0 | D14: -0.5 | E14: -0.7 | F14: 0.9 | G14: 1 | H14: =SQRT((($C14-$C$2)^2)+(($D14-$D$2)^2)+(($E14-$E$2)^2)+(($F14-$F$2)^2)+(($G14-$G$2)^2)) -> 3.93456 | I14: =SQRT((($C14-$C$3)^2)+(($D14-$D$3)^2)+(($E14-$E$3)^2)+(($F14-$F$3)^2)+(($G14-$G$3)^2)) -> 1.4073715 | J14: =SQRT((($C14-$C$4)^2)+(($D14-$D$4)^2)+(($E14-$E$4)^2)+(($F14-$F$4)^2)+(($G14-$G$4)^2)) -> 3.6702477 | K14: =MIN(H14:J14) -> 1.4073715 | L14: =IF(K14=J14, $J$9, IF(K14=I14, $I$9, IF(K14=H14, $H$9))) -> 2
B15: 6 | C15: 0 | D15: -0.1 | E15: -0.4 | F15: -1 | G15: 1 | H15: =SQRT((($C15-$C$2)^2)+(($D15-$D$2)^2)+(($E15-$E$2)^2)+(($F15-$F$2)^2)+(($G15-$G$2)^2)) -> 3.6906317 | I15: =SQRT((($C15-$C$3)^2)+(($D15-$D$3)^2)+(($E15-$E$3)^2)+(($F15-$F$3)^2)+(($G15-$G$3)^2)) -> 1.964865 | J15: =SQRT((($C15-$C$4)^2)+(($D15-$D$4)^2)+(($E15-$E$4)^2)+(($F15-$F$4)^2)+(($G15-$G$4)^2)) -> 3.1553028 | K15: =MIN(H15:J15) -> 1.964865 | L15: =IF(K15=J15, $J$9, IF(K15=I15, $I$9, IF(K15=H15, $H$9))) -> 2
B16: 7 | C16: 0 | D16: -0.1 | E16: -0.4 | F16: -1 | G16: 1 | H16: =SQRT((($C16-$C$2)^2)+(($D16-$D$2)^2)+(($E16-$E$2)^2)+(($F16-$F$2)^2)+(($G16-$G$2)^2)) -> 3.6906317 | I16: =SQRT((($C16-$C$3)^2)+(($D16-$D$3)^2)+(($E16-$E$3)^2)+(($F16-$F$3)^2)+(($G16-$G$3)^2)) -> 1.964865 | J16: =SQRT((($C16-$C$4)^2)+(($D16-$D$4)^2)+(($E16-$E$4)^2)+(($F16-$F$4)^2)+(($G16-$G$4)^2)) -> 3.1553028 | K16: =MIN(H16:J16) -> 1.964865 | L16: =IF(K16=J16, $J$9, IF(K16=I16, $I$9, IF(K16=H16, $H$9))) -> 2
B17: 8 | C17: 0 | D17: -0.5 | E17: -0.7 | F17: 0.9 | G17: 1 | H17: =SQRT((($C17-$C$2)^2)+(($D17-$D$2)^2)+(($E17-$E$2)^2)+(($F17-$F$2)^2)+(($G17-$G$2)^2)) -> 3.93456 | I17: =SQRT((($C17-$C$3)^2)+(($D17-$D$3)^2)+(($E17-$E$3)^2)+(($F17-$F$3)^2)+(($G17-$G$3)^2)) -> 1.4073715 | J17: =SQRT((($C17-$C$4)^2)+(($D17-$D$4)^2)+(($E17-$E$4)^2)+(($F17-$F$4)^2)+(($G17-$G$4)^2)) -> 3.6702477 | K17: =MIN(H17:J17) -> 1.4073715 | L17: =IF(K17=J17, $J$9, IF(K17=I17, $I$9, IF(K17=H17, $H$9))) -> 2
B18: 9 | C18: 0 | D18: -0.5 | E18: -0.7 | F18: 0.9 | G18: 1 | H18: =SQRT((($C18-$C$2)^2)+(($D18-$D$2)^2)+(($E18-$E$2)^2)+(($F18-$F$2)^2)+(($G18-$G$2)^2)) -> 3.93456 | I18: =SQRT((($C18-$C$3)^2)+(($D18-$D$3)^2)+(($E18-$E$3)^2)+(($F18-$F$3)^2)+(($G18-$G$3)^2)) -> 1.4073715 | J18: =SQRT((($C18-$C$4)^2)+(($D18-$D$4)^2)+(($E18-$E$4)^2)+(($F18-$F$4)^2)+(($G18-$G$4)^2)) -> 3.6702477 | K18: =MIN(H18:J18) -> 1.4073715 | L18: =IF(K18=J18, $J$9, IF(K18=I18, $I$9, IF(K18=H18, $H$9))) -> 2
B19: 10 | C19: 0 | D19: -0.1 | E19: -0.5 | F19: -1 | G19: 1 | H19: =SQRT((($C19-$C$2)^2)+(($D19-$D$2)^2)+(($E19-$E$2)^2)+(($F19-$F$2)^2)+(($G19-$G$2)^2)) -> 3.6909153 | I19: =SQRT((($C19-$C$3)^2)+(($D19-$D$3)^2)+(($E19-$E$3)^2)+(($F19-$F$3)^2)+(($G19-$G$3)^2)) -> 1.9727378 | J19: =SQRT((($C19-$C$4)^2)+(($D19-$D$4)^2)+(($E19-$E$4)^2)+(($F19-$F$4)^2)+(($G19-$G$4)^2)) -> 3.2165099 | K19: =MIN(H19:J19) -> 1.9727378 | L19: =IF(K19=J19, $J$9, IF(K19=I19, $I$9, IF(K19=H19, $H$9))) -> 2
B20: 11 | C20: 0 | D20: -0.1 | E20: -0.2 | F20: -1 | G20: 1 | H20: =SQRT((($C20-$C$2)^2)+(($D20-$D$2)^2)+(($E20-$E$2)^2)+(($F20-$F$2)^2)+(($G20-$G$2)^2)) -> 3.6981856 | I20: =SQRT((($C20-$C$3)^2)+(($D20-$D$3)^2)+(($E20-$E$3)^2)+(($F20-$F$3)^2)+(($G20-$G$3)^2)) -> 1.964356 | J20: =SQRT((($C20-$C$4)^2)+(($D20-$D$4)^2)+(($E20-$E$4)^2)+(($F20-$F$4)^2)+(($G20-$G$4)^2)) -> 3.0390682 | K20: =MIN(H20:J20) -> 1.964356 | L20: =IF(K20=J20, $J$9, IF(K20=I20, $I$9, IF(K20=H20, $H$9))) -> 2
B21: 12 | C21: 0 | D21: -0.1 | E21: -0.5 | F21: -1 | G21: 1 | H21: =SQRT((($C21-$C$2)^2)+(($D21-$D$2)^2)+(($E21-$E$2)^2)+(($F21-$F$2)^2)+(($G21-$G$2)^2)) -> 3.6909153 | I21: =SQRT((($C21-$C$3)^2)+(($D21-$D$3)^2)+(($E21-$E$3)^2)+(($F21-$F$3)^2)+(($G21-$G$3)^2)) -> 1.9727378 | J21: =SQRT((($C21-$C$4)^2)+(($D21-$D$4)^2)+(($E21-$E$4)^2)+(($F21-$F$4)^2)+(($G21-$G$4)^2)) -> 3.2165099 | K21: =MIN(H21:J21) -> 1.9727378 | L21: =IF(K21=J21, $J$9, IF(K21=I21, $I$9, IF(K21=H21, $H$9))) -> 2
... B135: 126 | C135: 0 | D135: -0.5 | E135: -0.7 | F135: -1 | G135: 6 | H135: =SQRT((($C135-$C$2)^2)+(($D135-$D$2)^2)+(($E135-$E$2)^2)+(($F135-$F$2)^2)+(($G135-$G$2)^2)) -> 1.4552454 | I135: =SQRT((($C135-$C$3)^2)+(($D135-$D$3)^2)+(($E135-$E$3)^2)+(($F135-$F$3)^2)+(($G135-$G$3)^2)) -> 4.0431458 | J135: =SQRT((($C135-$C$4)^2)+(($D135-$D$4)^2)+(($E135-$E$4)^2)+(($F135-$F$4)^2)+(($G135-$G$4)^2)) -> 4.3444944 | K135: =MIN(H135:J135) -> 1.4552454 | L135: =IF(K135=J135, $J$9, IF(K135=I135, $I$9, IF(K135=H135, $H$9))) -> 1

Sheet iterasi 6
A1: cluster | B1: ANGGOTA | C1: KABUPATEN | D1: KECAMATAN | E1: DESA | F1: jeniskelamin | G1: KELAS | H1: KESIMPULAN ITERSI 1 | K1: CLASTER | L1: ANGGOTA
A2: 1 | B2: ='iterasi 1'!L2 -> 43 | C2: =SUMIF('iterasi 5'!$L$10:$L$135,$A$2,'iterasi 5'!C$10:C$135)/$B$2 -> 0 | D2: =SUMIF('iterasi 5'!$L$10:$L$135,$A$2,'iterasi 5'!D$10:D$135)/$B$2 -> -0.30930233 | E2: =SUMIF('iterasi 5'!$L$10:$L$135,$A$2,'iterasi 5'!E$10:E$135)/$B$2 -> -0.40465116 | F2: =SUMIF('iterasi 5'!$L$10:$L$135,$A$2,'iterasi 5'!F$10:F$135)/$B$2 -> -0.15813953 | G2: =SUMIF('iterasi 5'!$L$10:$L$135,$A$2,'iterasi 5'!G$10:G$135)/$B$2 -> 4.6046512 | K2: 1 | L2: =COUNTIF($L$10:$L$135,A2) -> 43
A3: 2 | B3: ='iterasi 1'!L3 -> 60 | C3: =SUMIF('iterasi 5'!$L$10:$L$135,$A$3,'iterasi 5'!C$10:C$135)/$B$3 -> 0 | D3: =SUMIF('iterasi 5'!$L$10:$L$135,$A$3,'iterasi 5'!D$10:D$135)/$B$3 -> -0.33833333 | E3: =SUMIF('iterasi 5'!$L$10:$L$135,$A$3,'iterasi 5'!E$10:E$135)/$B$3 -> -0.29166667 | F3: =SUMIF('iterasi 5'!$L$10:$L$135,$A$3,'iterasi 5'!F$10:F$135)/$B$3 -> 0.16333333 | G3: =SUMIF('iterasi 5'!$L$10:$L$135,$A$3,'iterasi 5'!G$10:G$135)/$B$3 -> 2.3666667 | K3: 2 | L3: =COUNTIF($L$10:$L$135,A3) -> 71
A4: 3 | B4: ='iterasi 1'!L4 -> 23 | C4: =SUMIF('iterasi 5'!$L$10:$L$135,$A$4,'iterasi 5'!C$10:C$135)/$B$4 -> 0 | D4: =SUMIF('iterasi 5'!$L$10:$L$135,$A$4,'iterasi 5'!D$10:D$135)/$B$4 -> 1.4130435 | E4: =SUMIF('iterasi 5'!$L$10:$L$135,$A$4,'iterasi 5'!E$10:E$135)/$B$4 -> 1.426087 | F4: =SUMIF('iterasi 5'!$L$10:$L$135,$A$4,'iterasi 5'!F$10:F$135)/$B$4 -> -0.15652174 | G4: =SUMIF('iterasi 5'!$L$10:$L$135,$A$4,'iterasi 5'!G$10:G$135)/$B$4 -> 2.6956522 | K4: 3 | L4: =COUNTIF($L$10:$L$135,A4) -> 12
B8: NO | C8: DATA SET | H8: JARAK CETEROID | K8: TERDEKAT | L8: CLASTER YANG DI IKUTI
C9: KABUPATEN | D9: KECAMATAN | E9: DESA | F9: jeniskelamin | G9: KELAS | H9: 1 | I9: 2 | J9: 3
B10: 1 | C10: 0 | D10: -0.5 | E10: -0.7 | F10: -1 | G10: 1 | H10: =SQRT((($C10-$C$2)^2)+(($D10-$D$2)^2)+(($E10-$E$2)^2)+(($F10-$F$2)^2)+(($G10-$G$2)^2)) -> 3.7183109 | I10: =SQRT((($C10-$C$3)^2)+(($D10-$D$3)^2)+(($E10-$E$3)^2)+(($F10-$F$3)^2)+(($G10-$G$3)^2)) -> 1.8476998 | J10: =SQRT((($C10-$C$4)^2)+(($D10-$D$4)^2)+(($E10-$E$4)^2)+(($F10-$F$4)^2)+(($G10-$G$4)^2)) -> 3.4302584 | K10: =MIN(H10:J10) -> 1.8476998 | L10: =IF(K10=J10, $J$9, IF(K10=I10, $I$9, IF(K10=H10, $H$9))) -> 2
B11: 2 | C11: 0 | D11: -0.1 | E11: -0.5 | F11: 0.9 | G11: 1 | H11: =SQRT((($C11-$C$2)^2)+(($D11-$D$2)^2)+(($E11-$E$2)^2)+(($F11-$F$2)^2)+(($G11-$G$2)^2)) -> 3.7637838 | I11: =SQRT((($C11-$C$3)^2)+(($D11-$D$3)^2)+(($E11-$E$3)^2)+(($F11-$F$3)^2)+(($G11-$G$3)^2)) -> 1.5845066 | J11: =SQRT((($C11-$C$4)^2)+(($D11-$D$4)^2)+(($E11-$E$4)^2)+(($F11-$F$4)^2)+(($G11-$G$4)^2)) -> 3.1607888 | K11: =MIN(H11:J11) -> 1.5845066 | L11: =IF(K11=J11, $J$9, IF(K11=I11, $I$9, IF(K11=H11, $H$9))) -> 2
B12: 3 | C12: 0 | D12: -0.5 | E12: -0.7 | F12: 0.9 | G12: 1 | H12: =SQRT((($C12-$C$2)^2)+(($D12-$D$2)^2)+(($E12-$E$2)^2)+(($F12-$F$2)^2)+(($G12-$G$2)^2)) -> 3.7731639 | I12: =SQRT((($C12-$C$3)^2)+(($D12-$D$3)^2)+(($E12-$E$3)^2)+(($F12-$F$3)^2)+(($G12-$G$3)^2)) -> 1.6134831 | J12: =SQRT((($C12-$C$4)^2)+(($D12-$D$4)^2)+(($E12-$E$4)^2)+(($F12-$F$4)^2)+(($G12-$G$4)^2)) -> 3.4887613 | K12: =MIN(H12:J12) -> 1.6134831 | L12: =IF(K12=J12, $J$9, IF(K12=I12, $I$9, IF(K12=H12, $H$9))) -> 2
B13: 4 | C13: 0 | D13: -0.1 | E13: -0.5 | F13: 0.9 | G13: 1 | H13: =SQRT((($C13-$C$2)^2)+(($D13-$D$2)^2)+(($E13-$E$2)^2)+(($F13-$F$2)^2)+(($G13-$G$2)^2)) -> 3.7637838 | I13: =SQRT((($C13-$C$3)^2)+(($D13-$D$3)^2)+(($E13-$E$3)^2)+(($F13-$F$3)^2)+(($G13-$G$3)^2)) -> 1.5845066 | J13: =SQRT((($C13-$C$4)^2)+(($D13-$D$4)^2)+(($E13-$E$4)^2)+(($F13-$F$4)^2)+(($G13-$G$4)^2)) -> 3.1607888 | K13: =MIN(H13:J13) -> 1.5845066 | L13: =IF(K13=J13, $J$9, IF(K13=I13, $I$9, IF(K13=H13, $H$9))) -> 2
B14: 5 | C14: 0 | D14: -0.5 | E14: -0.7 | F14: 0.9 | G14: 1 | H14: =SQRT((($C14-$C$2)^2)+(($D14-$D$2)^2)+(($E14-$E$2)^2)+(($F14-$F$2)^2)+(($G14-$G$2)^2)) -> 3.7731639 | I14: =SQRT((($C14-$C$3)^2)+(($D14-$D$3)^2)+(($E14-$E$3)^2)+(($F14-$F$3)^2)+(($G14-$G$3)^2)) -> 1.6134831 | J14: =SQRT((($C14-$C$4)^2)+(($D14-$D$4)^2)+(($E14-$E$4)^2)+(($F14-$F$4)^2)+(($G14-$G$4)^2)) -> 3.4887613 | K14: =MIN(H14:J14) -> 1.6134831 | L14: =IF(K14=J14, $J$9, IF(K14=I14, $I$9, IF(K14=H14, $H$9))) -> 2
B15: 6 | C15: 0 | D15: -0.1 | E15: -0.4 | F15: -1 | G15: 1 | H15: =SQRT((($C15-$C$2)^2)+(($D15-$D$2)^2)+(($E15-$E$2)^2)+(($F15-$F$2)^2)+(($G15-$G$2)^2)) -> 3.707569 | I15: =SQRT((($C15-$C$3)^2)+(($D15-$D$3)^2)+(($E15-$E$3)^2)+(($F15-$F$3)^2)+(($G15-$G$3)^2)) -> 1.8137423 | J15: =SQRT((($C15-$C$4)^2)+(($D15-$D$4)^2)+(($E15-$E$4)^2)+(($F15-$F$4)^2)+(($G15-$G$4)^2)) -> 3.0348947 | K15: =MIN(H15:J15) -> 1.8137423 | L15: =IF(K15=J15, $J$9, IF(K15=I15, $I$9, IF(K15=H15, $H$9))) -> 2
B16: 7 | C16: 0 | D16: -0.1 | E16: -0.4 | F16: -1 | G16: 1 | H16: =SQRT((($C16-$C$2)^2)+(($D16-$D$2)^2)+(($E16-$E$2)^2)+(($F16-$F$2)^2)+(($G16-$G$2)^2)) -> 3.707569 | I16: =SQRT((($C16-$C$3)^2)+(($D16-$D$3)^2)+(($E16-$E$3)^2)+(($F16-$F$3)^2)+(($G16-$G$3)^2)) -> 1.8137423 | J16: =SQRT((($C16-$C$4)^2)+(($D16-$D$4)^2)+(($E16-$E$4)^2)+(($F16-$F$4)^2)+(($G16-$G$4)^2)) -> 3.0348947 | K16: =MIN(H16:J16) -> 1.8137423 | L16: =IF(K16=J16, $J$9, IF(K16=I16, $I$9, IF(K16=H16, $H$9))) -> 2
B17: 8 | C17: 0 | D17: -0.5 | E17: -0.7 | F17: 0.9 | G17: 1 | H17: =SQRT((($C17-$C$2)^2)+(($D17-$D$2)^2)+(($E17-$E$2)^2)+(($F17-$F$2)^2)+(($G17-$G$2)^2)) -> 3.7731639 | I17: =SQRT((($C17-$C$3)^2)+(($D17-$D$3)^2)+(($E17-$E$3)^2)+(($F17-$F$3)^2)+(($G17-$G$3)^2)) -> 1.6134831 | J17: =SQRT((($C17-$C$4)^2)+(($D17-$D$4)^2)+(($E17-$E$4)^2)+(($F17-$F$4)^2)+(($G17-$G$4)^2)) -> 3.4887613 | K17: =MIN(H17:J17) -> 1.6134831 | L17: =IF(K17=J17, $J$9, IF(K17=I17, $I$9, IF(K17=H17, $H$9))) -> 2
B18: 9 | C18: 0 | D18: -0.5 | E18: -0.7 | F18: 0.9 | G18: 1 | H18: =SQRT((($C18-$C$2)^2)+(($D18-$D$2)^2)+(($E18-$E$2)^2)+(($F18-$F$2)^2)+(($G18-$G$2)^2)) -> 3.7731639 | I18: =SQRT((($C18-$C$3)^2)+(($D18-$D$3)^2)+(($E18-$E$3)^2)+(($F18-$F$3)^2)+(($G18-$G$3)^2)) -> 1.6134831 | J18: =SQRT((($C18-$C$4)^2)+(($D18-$D$4)^2)+(($E18-$E$4)^2)+(($F18-$F$4)^2)+(($G18-$G$4)^2)) -> 3.4887613 | K18: =MIN(H18:J18) -> 1.6134831 | L18: =IF(K18=J18, $J$9, IF(K18=I18, $I$9, IF(K18=H18, $H$9))) -> 2
B19: 10 | C19: 0 | D19: -0.1 | E19: -0.5 | F19: -1 | G19: 1 | H19: =SQRT((($C19-$C$2)^2)+(($D19-$D$2)^2)+(($E19-$E$2)^2)+(($F19-$F$2)^2)+(($G19-$G$2)^2)) -> 3.708792 | I19: =SQRT((($C19-$C$3)^2)+(($D19-$D$3)^2)+(($E19-$E$3)^2)+(($F19-$F$3)^2)+(($G19-$G$3)^2)) -> 1.822451 | J19: =SQRT((($C19-$C$4)^2)+(($D19-$D$4)^2)+(($E19-$E$4)^2)+(($F19-$F$4)^2)+(($G19-$G$4)^2)) -> 3.0960949 | K19: =MIN(H19:J19) -> 1.822451 | L19: =IF(K19=J19, $J$9, IF(K19=I19, $I$9, IF(K19=H19, $H$9))) -> 2
B20: 11 | C20: 0 | D20: -0.1 | E20: -0.2 | F20: -1 | G20: 1 | H20: =SQRT((($C20-$C$2)^2)+(($D20-$D$2)^2)+(($E20-$E$2)^2)+(($F20-$F$2)^2)+(($G20-$G$2)^2)) -> 3.71321 | I20: =SQRT((($C20-$C$3)^2)+(($D20-$D$3)^2)+(($E20-$E$3)^2)+(($F20-$F$3)^2)+(($G20-$G$3)^2)) -> 1.8128232 | J20: =SQRT((($C20-$C$4)^2)+(($D20-$D$4)^2)+(($E20-$E$4)^2)+(($F20-$F$4)^2)+(($G20-$G$4)^2)) -> 2.9189298 | K20: =MIN(H20:J20) -> 1.8128232 | L20: =IF(K20=J20, $J$9, IF(K20=I20, $I$9, IF(K20=H20, $H$9))) -> 2
B21: 12 | C21: 0 | D21: -0.1 | E21: -0.5 | F21: -1 | G21: 1 | H21: =SQRT((($C21-$C$2)^2)+(($D21-$D$2)^2)+(($E21-$E$2)^2)+(($F21-$F$2)^2)+(($G21-$G$2)^2)) -> 3.708792 | I21: =SQRT((($C21-$C$3)^2)+(($D21-$D$3)^2)+(($E21-$E$3)^2)+(($F21-$F$3)^2)+(($G21-$G$3)^2)) -> 1.822451 | J21: =SQRT((($C21-$C$4)^2)+(($D21-$D$4)^2)+(($E21-$E$4)^2)+(($F21-$F$4)^2)+(($G21-$G$4)^2)) -> 3.0960949 | K21: =MIN(H21:J21) -> 1.822451 | L21: =IF(K21=J21, $J$9, IF(K21=I21, $I$9, IF(K21=H21, $H$9))) -> 2
... B135: 126 | C135: 0 | D135: -0.5 | E135: -0.7 | F135: -1 | G135: 6 | H135: =SQRT((($C135-$C$2)^2)+(($D135-$D$2)^2)+(($E135-$E$2)^2)+(($F135-$F$2)^2)+(($G135-$G$2)^2)) -> 1.6671305 | I135: =SQRT((($C135-$C$3)^2)+(($D135-$D$3)^2)+(($E135-$E$3)^2)+(($F135-$F$3)^2)+(($G135-$G$3)^2)) -> 3.840225 | J135: =SQRT((($C135-$C$4)^2)+(($D135-$D$4)^2)+(($E135-$E$4)^2)+(($F135-$F$4)^2)+(($G135-$G$4)^2)) -> 4.4508596 | K135: =MIN(H135:J135) -> 1.6671305 | L135: =IF(K135=J135, $J$9, IF(K135=I135, $I$9, IF(K135=H135, $H$9))) -> 1

Sheet iterasi 7
A1: cluster | B1: ANGGOTA | C1: KABUPATEN | D1: KECAMATAN | E1: DESA | F1: jeniskelamin | G1: KELAS | H1: KESIMPULAN ITERSI 1 | K1: CLASTER | L1: ANGGOTA
A2: 1 | B2: ='iterasi 1'!L2 -> 43 | C2: =SUMIF('iterasi 6'!$L$10:$L$135,$A$2,'iterasi 6'!C$10:C$135)/$B$2 -> 0 | D2: =SUMIF('iterasi 6'!$L$10:$L$135,$A$2,'iterasi 6'!D$10:D$135)/$B$2 -> -0.33255814 | E2: =SUMIF('iterasi 6'!$L$10:$L$135,$A$2,'iterasi 6'!E$10:E$135)/$B$2 -> -0.26046512 | F2: =SUMIF('iterasi 6'!$L$10:$L$135,$A$2,'iterasi 6'!F$10:F$135)/$B$2 -> -0.16046512 | G2: =SUMIF('iterasi 6'!$L$10:$L$135,$A$2,'iterasi 6'!G$10:G$135)/$B$2 -> 4.8604651 | K2: 1 | L2: =COUNTIF($L$10:$L$135,A2) -> 43
A3: 2 | B3: ='iterasi 1'!L3 -> 60 | C3: =SUMIF('iterasi 6'!$L$10:$L$135,$A$3,'iterasi 6'!C$10:C$135)/$B$3 -> 0 | D3: =SUMIF('iterasi 6'!$L$10:$L$135,$A$3,'iterasi 6'!D$10:D$135)/$B$3 -> -0.34 | E3: =SUMIF('iterasi 6'!$L$10:$L$135,$A$3,'iterasi 6'!E$10:E$135)/$B$3 -> -0.28 | F3: =SUMIF('iterasi 6'!$L$10:$L$135,$A$3,'iterasi 6'!F$10:F$135)/$B$3 -> 0.14666667 | G3: =SUMIF('iterasi 6'!$L$10:$L$135,$A$3,'iterasi 6'!G$10:G$135)/$B$3 -> 2.4166667 | K3: 2 | L3: =COUNTIF($L$10:$L$135,A3) -> 70
A4: 3 | B4: ='iterasi 1'!L4 -> 23 | C4: =SUMIF('iterasi 6'!$L$10:$L$135,$A$4,'iterasi 6'!C$10:C$135)/$B$4 -> 0 | D4: =SUMIF('iterasi 6'!$L$10:$L$135,$A$4,'iterasi 6'!D$10:D$135)/$B$4 -> 1.4608696 | E4: =SUMIF('iterasi 6'!$L$10:$L$135,$A$4,'iterasi 6'!E$10:E$135)/$B$4 -> 1.126087 | F4: =SUMIF('iterasi 6'!$L$10:$L$135,$A$4,'iterasi 6'!F$10:F$135)/$B$4 -> -0.10869565 | G4: =SUMIF('iterasi 6'!$L$10:$L$135,$A$4,'iterasi 6'!G$10:G$135)/$B$4 -> 2.0869565 | K4: 3 | L4: =COUNTIF($L$10:$L$135,A4) -> 13
B8: NO | C8: DATA SET | H8: JARAK CETEROID | K8: TERDEKAT | L8: CLASTER YANG DI IKUTI
C9: KABUPATEN | D9: KECAMATAN | E9: DESA | F9: jeniskelamin | G9: KELAS | H9: 1 | I9: 2 | J9: 3
B10: 1 | C10: 0 | D10: -0.5 | E10: -0.7 | F10: -1 | G10: 1 | H10: =SQRT((($C10-$C$2)^2)+(($D10-$D$2)^2)+(($E10-$E$2)^2)+(($F10-$F$2)^2)+(($G10-$G$2)^2)) -> 3.9785974 | I10: =SQRT((($C10-$C$3)^2)+(($D10-$D$3)^2)+(($E10-$E$3)^2)+(($F10-$F$3)^2)+(($G10-$G$3)^2)) -> 1.8771758 | J10: =SQRT((($C10-$C$4)^2)+(($D10-$D$4)^2)+(($E10-$E$4)^2)+(($F10-$F$4)^2)+(($G10-$G$4)^2)) -> 3.0258058 | K10: =MIN(H10:J10) -> 1.8771758 | L10: =IF(K10=J10, $J$9, IF(K10=I10, $I$9, IF(K10=H10, $H$9))) -> 2
B11: 2 | C11: 0 | D11: -0.1 | E11: -0.5 | F11: 0.9 | G11: 1 | H11: =SQRT((($C11-$C$2)^2)+(($D11-$D$2)^2)+(($E11-$E$2)^2)+(($F11-$F$2)^2)+(($G11-$G$2)^2)) -> 4.017367 | I11: =SQRT((($C11-$C$3)^2)+(($D11-$D$3)^2)+(($E11-$E$3)^2)+(($F11-$F$3)^2)+(($G11-$G$3)^2)) -> 1.6372097 | J11: =SQRT((($C11-$C$4)^2)+(($D11-$D$4)^2)+(($E11-$E$4)^2)+(($F11-$F$4)^2)+(($G11-$G$4)^2)) -> 2.6980389 | K11: =MIN(H11:J11) -> 1.6372097 | L11: =IF(K11=J11, $J$9, IF(K11=I11, $I$9, IF(K11=H11, $H$9))) -> 2
B12: 3 | C12: 0 | D12: -0.5 | E12: -0.7 | F12: 0.9 | G12: 1 | H12: =SQRT((($C12-$C$2)^2)+(($D12-$D$2)^2)+(($E12-$E$2)^2)+(($F12-$F$2)^2)+(($G12-$G$2)^2)) -> 4.0310054 | I12: =SQRT((($C12-$C$3)^2)+(($D12-$D$3)^2)+(($E12-$E$3)^2)+(($F12-$F$3)^2)+(($G12-$G$3)^2)) -> 1.66627 | J12: =SQRT((($C12-$C$4)^2)+(($D12-$D$4)^2)+(($E12-$E$4)^2)+(($F12-$F$4)^2)+(($G12-$G$4)^2)) -> 3.0624409 | K12: =MIN(H12:J12) -> 1.66627 | L12: =IF(K12=J12, $J$9, IF(K12=I12, $I$9, IF(K12=H12, $H$9))) -> 2
B13: 4 | C13: 0 | D13: -0.1 | E13: -0.5 | F13: 0.9 | G13: 1 | H13: =SQRT((($C13-$C$2)^2)+(($D13-$D$2)^2)+(($E13-$E$2)^2)+(($F13-$F$2)^2)+(($G13-$G$2)^2)) -> 4.017367 | I13: =SQRT((($C13-$C$3)^2)+(($D13-$D$3)^2)+(($E13-$E$3)^2)+(($F13-$F$3)^2)+(($G13-$G$3)^2)) -> 1.6372097 | J13: =SQRT((($C13-$C$4)^2)+(($D13-$D$4)^2)+(($E13-$E$4)^2)+(($F13-$F$4)^2)+(($G13-$G$4)^2)) -> 2.6980389 | K13: =MIN(H13:J13) -> 1.6372097 | L13: =IF(K13=J13, $J$9, IF(K13=I13, $I$9, IF(K13=H13, $H$9))) -> 2
B14: 5 | C14: 0 | D14: -0.5 | E14: -0.7 | F14: 0.9 | G14: 1 | H14: =SQRT((($C14-$C$2)^2)+(($D14-$D$2)^2)+(($E14-$E$2)^2)+(($F14-$F$2)^2)+(($G14-$G$2)^2)) -> 4.0310054 | I14: =SQRT((($C14-$C$3)^2)+(($D14-$D$3)^2)+(($E14-$E$3)^2)+(($F14-$F$3)^2)+(($G14-$G$3)^2)) -> 1.66627 | J14: =SQRT((($C14-$C$4)^2)+(($D14-$D$4)^2)+(($E14-$E$4)^2)+(($F14-$F$4)^2)+(($G14-$G$4)^2)) -> 3.0624409 | K14: =MIN(H14:J14) -> 1.66627 | L14: =IF(K14=J14, $J$9, IF(K14=I14, $I$9, IF(K14=H14, $H$9))) -> 2
B15: 6 | C15: 0 | D15: -0.1 | E15: -0.4 | F15: -1 | G15: 1 | H15: =SQRT((($C15-$C$2)^2)+(($D15-$D$2)^2)+(($E15-$E$2)^2)+(($F15-$F$2)^2)+(($G15-$G$2)^2)) -> 3.9599953 | I15: =SQRT((($C15-$C$3)^2)+(($D15-$D$3)^2)+(($E15-$E$3)^2)+(($F15-$F$3)^2)+(($G15-$G$3)^2)) -> 1.8422239 | J15: =SQRT((($C15-$C$4)^2)+(($D15-$D$4)^2)+(($E15-$E$4)^2)+(($F15-$F$4)^2)+(($G15-$G$4)^2)) -> 2.5963731 | K15: =MIN(H15:J15) -> 1.8422239 | L15: =IF(K15=J15, $J$9, IF(K15=I15, $I$9, IF(K15=H15, $H$9))) -> 2
B16: 7 | C16: 0 | D16: -0.1 | E16: -0.4 | F16: -1 | G16: 1 | H16: =SQRT((($C16-$C$2)^2)+(($D16-$D$2)^2)+(($E16-$E$2)^2)+(($F16-$F$2)^2)+(($G16-$G$2)^2)) -> 3.9599953 | I16: =SQRT((($C16-$C$3)^2)+(($D16-$D$3)^2)+(($E16-$E$3)^2)+(($F16-$F$3)^2)+(($G16-$G$3)^2)) -> 1.8422239 | J16: =SQRT((($C16-$C$4)^2)+(($D16-$D$4)^2)+(($E16-$E$4)^2)+(($F16-$F$4)^2)+(($G16-$G$4)^2)) -> 2.5963731 | K16: =MIN(H16:J16) -> 1.8422239 | L16: =IF(K16=J16, $J$9, IF(K16=I16, $I$9, IF(K16=H16, $H$9))) -> 2
B17: 8 | C17: 0 | D17: -0.5 | E17: -0.7 | F17: 0.9 | G17: 1 | H17: =SQRT((($C17-$C$2)^2)+(($D17-$D$2)^2)+(($E17-$E$2)^2)+(($F17-$F$2)^2)+(($G17-$G$2)^2)) -> 4.0310054 | I17: =SQRT((($C17-$C$3)^2)+(($D17-$D$3)^2)+(($E17-$E$3)^2)+(($F17-$F$3)^2)+(($G17-$G$3)^2)) -> 1.66627 | J17: =SQRT((($C17-$C$4)^2)+(($D17-$D$4)^2)+(($E17-$E$4)^2)+(($F17-$F$4)^2)+(($G17-$G$4)^2)) -> 3.0624409 | K17: =MIN(H17:J17) -> 1.66627 | L17: =IF(K17=J17, $J$9, IF(K17=I17, $I$9, IF(K17=H17, $H$9))) -> 2
B18: 9 | C18: 0 | D18: -0.5 | E18: -0.7 | F18: 0.9 | G18: 1 | H18: =SQRT((($C18-$C$2)^2)+(($D18-$D$2)^2)+(($E18-$E$2)^2)+(($F18-$F$2)^2)+(($G18-$G$2)^2)) -> 4.0310054 | I18: =SQRT((($C18-$C$3)^2)+(($D18-$D$3)^2)+(($E18-$E$3)^2)+(($F18-$F$3)^2)+(($G18-$G$3)^2)) -> 1.66627 | J18: =SQRT((($C18-$C$4)^2)+(($D18-$D$4)^2)+(($E18-$E$4)^2)+(($F18-$F$4)^2)+(($G18-$G$4)^2)) -> 3.0624409 | K18: =MIN(H18:J18) -> 1.66627 | L18: =IF(K18=J18, $J$9, IF(K18=I18, $I$9, IF(K18=H18, $H$9))) -> 2
B19: 10 | C19: 0 | D19: -0.1 | E19: -0.5 | F19: -1 | G19: 1 | H19: =SQRT((($C19-$C$2)^2)+(($D19-$D$2)^2)+(($E19-$E$2)^2)+(($F19-$F$2)^2)+(($G19-$G$2)^2)) -> 3.9647787 | I19: =SQRT((($C19-$C$3)^2)+(($D19-$D$3)^2)+(($E19-$E$3)^2)+(($F19-$F$3)^2)+(($G19-$G$3)^2)) -> 1.8514289 | J19: =SQRT((($C19-$C$4)^2)+(($D19-$D$4)^2)+(($E19-$E$4)^2)+(($F19-$F$4)^2)+(($G19-$G$4)^2)) -> 2.656383 | K19: =MIN(H19:J19) -> 1.8514289 | L19: =IF(K19=J19, $J$9, IF(K19=I19, $I$9, IF(K19=H19, $H$9))) -> 2
B20: 11 | C20: 0 | D20: -0.1 | E20: -0.2 | F20: -1 | G20: 1 | H20: =SQRT((($C20-$C$2)^2)+(($D20-$D$2)^2)+(($E20-$E$2)^2)+(($F20-$F$2)^2)+(($G20-$G$2)^2)) -> 3.9579981 | I20: =SQRT((($C20-$C$3)^2)+(($D20-$D$3)^2)+(($E20-$E$3)^2)+(($F20-$F$3)^2)+(($G20-$G$3)^2)) -> 1.8400513 | J20: =SQRT((($C20-$C$4)^2)+(($D20-$D$4)^2)+(($E20-$E$4)^2)+(($F20-$F$4)^2)+(($G20-$G$4)^2)) -> 2.4840931 | K20: =MIN(H20:J20) -> 1.8400513 | L20: =IF(K20=J20, $J$9, IF(K20=I20, $I$9, IF(K20=H20, $H$9))) -> 2
B21: 12 | C21: 0 | D21: -0.1 | E21: -0.5 | F21: -1 | G21: 1 | H21: =SQRT((($C21-$C$2)^2)+(($D21-$D$2)^2)+(($E21-$E$2)^2)+(($F21-$F$2)^2)+(($G21-$G$2)^2)) -> 3.9647787 | I21: =SQRT((($C21-$C$3)^2)+(($D21-$D$3)^2)+(($E21-$E$3)^2)+(($F21-$F$3)^2)+(($G21-$G$3)^2)) -> 1.8514289 | J21: =SQRT((($C21-$C$4)^2)+(($D21-$D$4)^2)+(($E21-$E$4)^2)+(($F21-$F$4)^2)+(($G21-$G$4)^2)) -> 2.656383 | K21: =MIN(H21:J21) -> 1.8514289 | L21: =IF(K21=J21, $J$9, IF(K21=I21, $I$9, IF(K21=H21, $H$9))) -> 2
... B135: 126 | C135: 0 | D135: -0.5 | E135: -0.7 | F135: -1 | G135: 6 | H135: =SQRT((($C135-$C$2)^2)+(($D135-$D$2)^2)+(($E135-$E$2)^2)+(($F135-$F$2)^2)+(($G135-$G$2)^2)) -> 1.4915047 | I135: =SQRT((($C135-$C$3)^2)+(($D135-$D$3)^2)+(($E135-$E$3)^2)+(($F135-$F$3)^2)+(($G135-$G$3)^2)) -> 3.7890793 | J135: =SQRT((($C135-$C$4)^2)+(($D135-$D$4)^2)+(($E135-$E$4)^2)+(($F135-$F$4)^2)+(($G135-$G$4)^2)) -> 4.8255503 | K135: =MIN(H135:J135) -> 1.4915047 | L135: =IF(K135=J135, $J$9, IF(K135=I135, $I$9, IF(K135=H135, $H$9))) -> 1

Sheet iterasi 8
A1: cluster | B1: ANGGOTA | C1: KABUPATEN | D1: KECAMATAN | E1: DESA | F1: jeniskelamin | G1: KELAS | H1: KESIMPULAN ITERSI 1 | K1: CLASTER | L1: ANGGOTA | Q1: DBI | R1: Cluster | S1: Nilai
A2: 1 | B2: ='iterasi 1'!L2 -> 43 | C2: =SUMIF('iterasi 7'!$L$10:$L$135,$A$2,'iterasi 7'!C$10:C$135)/$B$2 -> 0 | D2: =SUMIF('iterasi 7'!$L$10:$L$135,$A$2,'iterasi 7'!D$10:D$135)/$B$2 -> -0.33255814 | E2: =SUMIF('iterasi 7'!$L$10:$L$135,$A$2,'iterasi 7'!E$10:E$135)/$B$2 -> -0.26046512 | F2: =SUMIF('iterasi 7'!$L$10:$L$135,$A$2,'iterasi 7'!F$10:F$135)/$B$2 -> -0.16046512 | G2: =SUMIF('iterasi 7'!$L$10:$L$135,$A$2,'iterasi 7'!G$10:G$135)/$B$2 -> 4.8604651 | K2: 1 | L2: =COUNTIF($L$10:$L$135,A2) -> 43 | Q2: Si | R2: 1 | S2: =AVERAGEIF($L$10:$L$135,1,$K$10:$K$135) -> 1.4209783
A3: 2 | B3: ='iterasi 1'!L3 -> 60 | C3: =SUMIF('iterasi 7'!$L$10:$L$135,$A$3,'iterasi 7'!C$10:C$135)/$B$3 -> 0 | D3: =SUMIF('iterasi 7'!$L$10:$L$135,$A$3,'iterasi 7'!D$10:D$135)/$B$3 -> -0.35 | E3: =SUMIF('iterasi 7'!$L$10:$L$135,$A$3,'iterasi 7'!E$10:E$135)/$B$3 -> -0.285 | F3: =SUMIF('iterasi 7'!$L$10:$L$135,$A$3,'iterasi 7'!F$10:F$135)/$B$3 -> 0.16333333 | G3: =SUMIF('iterasi 7'!$L$10:$L$135,$A$3,'iterasi 7'!G$10:G$135)/$B$3 -> 2.4 | K3: 2 | L3: =COUNTIF($L$10:$L$135,A3) -> 70 | Q3: Si | R3: 2 | S3: =AVERAGEIF($L$10:$L$135,2,$K$10:$K$135) -> 1.4032509
A4: 3 | B4: ='iterasi 1'!L4 -> 23 | C4: =SUMIF('iterasi 7'!$L$10:$L$135,$A$4,'iterasi 7'!C$10:C$135)/$B$4 -> 0 | D4: =SUMIF('iterasi 7'!$L$10:$L$135,$A$4,'iterasi 7'!D$10:D$135)/$B$4 -> 1.4869565 | E4: =SUMIF('iterasi 7'!$L$10:$L$135,$A$4,'iterasi 7'!E$10:E$135)/$B$4 -> 1.1391304 | F4: =SUMIF('iterasi 7'!$L$10:$L$135,$A$4,'iterasi 7'!F$10:F$135)/$B$4 -> -0.15217391 | G4: =SUMIF('iterasi 7'!$L$10:$L$135,$A$4,'iterasi 7'!G$10:G$135)/$B$4 -> 2.1304348 | K4: 3 | L4: =COUNTIF($L$10:$L$135,A4) -> 13 | Q4: Si | R4: 3 | S4: =AVERAGEIF($L$10:$L$135,3,$K$10:$K$135) -> 2.802566
Q5: Mij | R5: M12 | S5: =SQRT((C2-C3)^2+(D2-D3)^2+(E2-E3)^2+(F2-F3)^2+(G2-G3)^2) -> 2.4818622
Q6: Mij | R6: M13 | S6: =SQRT((C2-C4)^2+(D2-D4)^2+(E2-E4)^2+(F2-F4)^2+(G2-G4)^2) -> 3.5668804
Q7: Mij | R7: M23 | S7: =SQRT((C3-C4)^2+(D3-D4)^2+(E3-E4)^2+(F3-F4)^2+(G3-G4)^2) -> 2.3610944
B8: NO | C8: DATA SET | H8: JARAK CETEROID | K8: TERDEKAT | L8: CLASTER YANG DI IKUTI | M8: claster Pada dataset | N8: hasil pencocokan | O8: akurasi | Q8: Rij | R8: R12 | S8: =(S2+S3)/S5 -> 1.1379476
